Workbook

Sheet 表紙
B4: 負荷試験 実施ガイド ｜ 第2.0版
B5: Apache JMeter 負荷試験 実践ガイド
B6: Windows 11 でシナリオ作成 → Linux サーバで CLI 実行 → Excel で分析・報告
B7: Amazon Cognito（OAuth 2.0 client_credentials）＋ Amazon API Gateway（APIキー）対応版
B10: 文書情報
B11: 文書名 | D11: Apache JMeter 負荷試験 実践ガイド
B12: 版数 | D12: 第2.0版
B13: 作成日 | D13: 2026年10月4日
B14: 作成者
B15: 対象読者 | D15: JMeter を初めて使う方（負荷試験の実施担当者）。Linux・AWS・Excel の基本操作ができることを前提とします。
B16: 対象バージョン | D16: Apache JMeter 5.6.3（2026年10月時点の最新安定版）／ Java 17 または 21（LTS）
B17: 対象環境 | D17: シナリオ作成・分析端末：Windows 11 ／ 負荷生成（実行）サーバ：Linux（Amazon Linux 2023・RHEL 系・Ubuntu）
B18: 対象システム | D18: Amazon Cognito ユーザープール（トークンエンドポイント）＋ Amazon API Gateway（REST API・APIキー）
B19: 表記について | D19: JMeter の画面項目名は英語表示で記載しています（JMeter 5.6.3 は既定で英語表示で起動します）。ホスト名・ID・キー・IPアドレス等はすべて説明用のダミー値です。現場の値に読み替えてください。
B21: 改訂履歴
B22: 版 | C22: 日付 | D22: 改訂内容 | H22: 担当
B23: 1.0 | C23: 2026/10/04 | D23: 初版作成
B24: 2.0 | C24: 2026/10/04 | D24: 全面見直し。負荷条件の見積り表（00）、評価区間の分析（15・17・18）、Power Query の M コード（14）、実施記録（19）、完成版 jmx（付録E）を追加。JMeter 5.6.3 での実行検証の結果を反映（結果ファイルの件数の数え方、引用符の中の改行の取り込み）。表の見やすさを改善
B29: ご利用にあたって
B30: ・最初に「目次」シートを開き、「このガイドの使い方」を読んでから、上から順にシートを進めてください。
B31: ・負荷試験は、対象システムの責任者の承認と関係者への事前連絡のうえで実施してください（09_注意点 参照）。
B32: ・クライアントシークレット・APIキー・アクセストークンは、本ブック・画面キャプチャ・報告書に記載しないでください。
B33: ・白地・点線枠のセルは入力欄、破線枠の「画像貼付エリア」はスクリーンショットの貼り付け場所です。

Sheet 目次
B1: 目次 ／ このガイドの使い方
B2: このブックは、JMeter の入手から報告書の提出までを、作業の順番どおりに並べています。上から順に進めてください。 | F2: ▲ 目次へ戻る
B4: 1. このガイドの使い方
B6: ・ | C6: シートは作業の順番に並んでいます。下の「シート一覧」のシート名をクリックすると、そのシートへ移動します。各シート右上の「▲ 目次へ戻る」で、このシートに戻れます。
B7: ・ | C7: 灰色の背景のセルは、コマンド・設定ファイル・スクリプトです。セルを選択して Ctrl+C でコピーし、PowerShell・Linux のターミナル・JMeter の入力欄・メモ帳に貼り付けて使います。
B8: ・ | C8: 複数行のコマンドは、行をまとめて選択してコピーできます。ただし、ターミナルに貼り付けると末尾の改行によってすぐに実行されることがあります。内容を確認してから実行したい場合は、いったんメモ帳に貼り付けて確認してください。
B9: ・ | C9: セルの一部だけをコピーしたい場合は、セルをダブルクリック（または F2 キー）して編集状態にしてから、必要な文字だけを選択してコピーします。
B10: ・ | C10: 「画像貼付エリア」と書かれた破線の枠は、後からスクリーンショットを貼り付けるための場所です。貼り付け方は下の「4. 画像の貼り付け手順」、全体の一覧は「付録D_画像差込一覧」を参照してください。
B11: ・ | C11: 白地で点線枠のセルは入力欄です。現場の情報（担当者名・実施日・目標値など）を記入してください。
B12: ・ | C12: シナリオを作るときは、完成版のシナリオ（付録E_完成版jmx）と見比べながら進めると、設定漏れに気付きやすくなります。
B13: ・ | C13: 負荷試験の当日は、実行ごとの条件と結果を「19_実施記録」に記録します。報告書（18）を書くときの元資料になります。
B14: ・ | C14: 画面の項目名は JMeter の英語表示に合わせ、［ ］で囲んで表記しています（例：［Add］→［Sampler］→［HTTP Request］）。「→」は、メニューを順にたどる操作を表します。
B15: ・ | C15: このブックのフォント（Meiryo UI）では、半角の「\」（バックスラッシュ）が「¥」（円記号）の形で表示されます。コピーして貼り付けると正しく「\」になります。Linux のコマンドや正規表現で「¥」と見えている文字は、すべてバックスラッシュとして入力してください。
B17: 2. 表記・色分けの凡例
B19: 表示 | D19: 意味
B20: 黒い帯の見出し | D20: 章（大きな区切り）の見出しです。
B21: 灰色の帯の見出し | D21: 節（章の中の区切り）の見出しです。
B22: 濃い灰色の表見出し | D22: 表の項目名です。
B23: 薄い灰色のセル | D23: コマンド・設定値・スクリプトです（そのままコピーして使えます）。
B24: 注意 | D24: 守らないと失敗や事故につながる事項です。必ず読んでください。
B25: ポイント | D25: 理解を助けるコツや、迷いやすい点の説明です。
B26: 参考 | D26: 知っておくと役立つ補足情報です。
B27: 白地・点線枠 | D27: 入力欄です。現場の情報を記入します。
B28: 破線枠 | D28: 画像貼付エリアです。スクリーンショットを貼り付けます。
B31: 3. シート一覧（クリックで移動）
B33: No. | C33: シート名 | D33: 内容 | F33: 主な作業場所
B34: 1 | C34: 00_全体像と準備 | D34: 作業の全体の流れ、作業ステップ一覧、事前準備チェックリスト、接続情報の記入表、負荷条件（スレッド数）の見積り表 | F34: ―
B35: 2 | C35: 01_Windows導入 | D35: Java のインストール、JMeter の入手・ハッシュ確認・展開、起動確認、初期設定、Plugins Manager | F35: Windows 端末
B36: 3 | C36: 02_画面の基本 | D36: 画面構成、ツールバー・ショートカット、テスト要素の種類、スコープ、実行順序、変数とプロパティ | F36: Windows 端末
B37: 4 | C37: 03_機能一覧 | D37: 主なテスト要素の用途と追加方法、関数、メニュー機能、プラグインの一覧 | F37: Windows 端末
B38: 5 | C38: 04_シナリオ作成 | D38: Cognito トークン取得、Base64 の作り方、APIキー（X-API-ID）ヘッダー、トークンの保持・共有、API 呼び出し、CSV データ | F38: Windows 端末
B39: 6 | C39: 05_正規表現抽出 | D39: 設定項目の意味、正規表現の組み立て方、記号の一覧、抽出例、RegExp Tester での確認、JSON Extractor との使い分け | F39: Windows 端末
B40: 7 | C40: 06_GUI実行 | D40: 実行前チェック、実行手順、View Results Tree の見方、停止方法、エラー時の切り分け | F40: Windows 端末
B41: 8 | C41: 07_結果の見方 | D41: 主な指標の定義、Summary／Aggregate Report、HTML レポートの構成と生成方法、JTL の列の意味 | F41: Windows 端末
B42: 9 | C42: 08_確認観点 | D42: 確認の流れ、観点一覧（判断の目安と NG 時に疑うこと）、AWS 側で見るメトリクス、判定の考え方 | F42: Windows 端末
B43: 10 | C43: 09_注意点 | D43: 実施前の合意、AWS の制限・課金、セキュリティ、JMeter・ファイル・時刻・Excel・報告の注意点 | F43: ―
B44: 11 | C44: 10_Linux準備 | D44: サーバ要件、SSH 接続（踏み台・鍵の権限）、Java・JMeter の導入、PATH、作業フォルダ、OS 設定、プラグイン | F44: Linux 実行サーバ
... B58: 25 | C58: 付録E_完成版jmx | D58: 04 の手順で作るシナリオの完成形（要素と設定値の一覧、jmx ファイルの全文、ファイルの作り方と確認方法） | F58: Windows 端末
B61: 4. 画像の貼り付け手順（スクリーンショットの差し込み方）
B63: No. | C63: 手順 | D63: 操作内容（詳しい手順） | E63: 入力値・設定値 | F63: 確認ポイント・補足
...

Sheet 00_全体像と準備
B1: 00 全体像と事前準備
B2: このガイドで行う作業の全体の流れと、作業を始める前にそろえておく情報・権限を確認します。 | F2: ▲ 目次へ戻る
B4: 1. このガイドで行う作業
B6: 本ガイドでは、Windows 11 の端末で JMeter のシナリオ（.jmx ファイル）を作成して動作を確認し、そのシナリオを Linux の負荷生成サーバ（以下「実行サーバ」）へ転送して、コマンド（CLI）で負荷試験を実行します。実行結果（.jtl・.log・HTMLレポート）を端末に回収し、Excel で分析して報告書を作成・提出するまでを扱います。
B7: 試験対象は、Amazon Cognito のトークンエンドポイントでアクセストークンを取得し、そのトークンと APIキーをヘッダーに付けて Amazon API Gateway の API を呼び出す、という構成を想定しています。
B8: ポイント | C8: JMeter の画面（GUI）は「シナリオを作る・動作を確かめる」ための道具です。実際に負荷をかける試験は、画面を使わないコマンド実行（CLI モード）で行います。これは JMeter 公式の推奨事項です。
B11: 2. 全体の流れ（どこで何をするか）
B13: No. | C13: Windows 11 端末（作成・分析） | E13: Linux 実行サーバ（負荷生成） | F13: AWS（試験対象）
B14: ① | C14: 【導入】Java と JMeter をインストールする（01）
B15: ② | C15: 【作成】JMeter の画面でシナリオ（.jmx）を作る（04・05）
B16: ③ | C16: 【確認】1ユーザーで実行し、正しく動くことを確かめる（06・07） ――HTTPS――▶ | F16: Cognito がトークンを発行／API Gateway が応答
B17: ④ | C17: 【転送】jmx・CSV・properties を scp で送る（11） ══SSH══▶ | E17: 【配置】作業フォルダに置く（11）
B18: ⑤ | C18: 【記録】実行条件と結果を記録する（19） | E18: 【実行】jmeter -n で負荷試験を実行し、画面で監視する（12） ――HTTPS――▶ | F18: 負荷を受ける（CloudWatch で監視）
B19: ⑥ | E19: 【出力】result.jtl・jmeter.log・HTMLレポートができる（12）
B20: ⑦ | C20: 【回収】結果を scp で受け取り、展開する（13） ◀══SSH══ | E20: 【圧縮】結果フォルダを tar.gz にまとめる（13）
B21: ⑧ | C21: 【分析】Excel に取り込み、集計・グラフ化する（14・15・17）
B22: ⑨ | C22: 【報告】報告書を作成して提出する（08・18）
B24: ※ かっこ内の番号は、詳しい手順が書かれているシートの番号です。
B25: ［ 画像貼付エリア ］ 図00-1 試験環境の構成図（現場の構成図を貼り付け） 撮影対象：Windows 端末・踏み台・実行サーバ・Cognito・API Gateway・バックエンドの位置関係と通信経路（ポート番号）が分かる図 （この枠の左上のセルを選択して Ctrl+V で貼り付け、枠内に収まるようにサイズを調整してください）
B45: 図00-1 試験環境の構成図（現場の構成図を貼り付け）
B48: 通信経路のまとめ
B50: 通信元 | D50: 通信先 | E50: 用途・プロトコル | F50: 備考
B51: Windows 端末 | D51: 実行サーバ（または踏み台） | E51: SSH（TCP 22）：ログイン・ファイル転送（scp） | F51: 秘密鍵（.pem）が必要
B52: Windows 端末 | D52: Cognito・API Gateway | E52: HTTPS（TCP 443）：GUI での動作確認 | F52: 社内プロキシ経由の場合は JMeter にプロキシ設定が必要（01 参照）
B53: 実行サーバ | D53: Cognito・API Gateway | E53: HTTPS（TCP 443）：負荷試験の本番 | F53: セキュリティグループ・WAF で遮断されないこと
B54: 実行サーバ | D54: インターネット（任意） | E54: HTTPS：Java・JMeter のダウンロード | F54: 接続できない場合は端末から転送（10・11 参照）
B57: 3. 作業ステップ一覧
B59: No. | C59: 作業 | D59: 実施場所／主なツール | E59: 成果物 | F59: 参照シート
B60: 1 | C60: Java・JMeter の導入と初期設定 | D60: Windows 端末／ブラウザ・PowerShell | E60: 起動できる JMeter | F60: 01
B61: 2 | C61: 画面の基本操作と機能を理解する | D61: Windows 端末／JMeter（GUI） | E61: ― | F61: 02・03
B62: 3 | C62: シナリオを作成する | D62: Windows 端末／JMeter（GUI） | E62: api_loadtest.jmx、env_stg.properties | F62: 04・05
B63: 4 | C63: 1ユーザーで動作確認する | D63: Windows 端末／JMeter（GUI） | E63: 動作確認結果（画面キャプチャ） | F63: 06・07
B64: 5 | C64: 実行サーバを準備する | D64: Linux 実行サーバ／ssh・dnf（apt） | E64: JMeter 実行環境 | F64: 10
B65: 6 | C65: ファイルを転送・配置する | D65: Windows → Linux／scp・WinSCP | E65: 配置済みのシナリオ一式 | F65: 11
B66: 7 | C66: CLI で負荷試験を実行・監視し、記録する | D66: Linux 実行サーバ／jmeter・tmux | E66: result.jtl、jmeter.log、report/、実施記録 | F66: 00・12・19
B67: 8 | C67: 結果を回収する | D67: Linux → Windows／tar・scp | E67: 結果一式（tar.gz） | F67: 13
B68: 9 | C68: Excel に取り込んで分析する | D68: Windows 端末／Excel（Power Query） | E68: 分析ブック | F68: 14・15・17
B69: 10 | C69: 報告書を作成・提出する | D69: Windows 端末／Excel | E69: 試験結果報告書 | F69: 08・18
B72: 4. 事前準備チェックリスト（作業前に必ず確認）
B74: 次の情報・権限がそろっていないと、途中で作業が止まります。担当者に確認し、［状況］欄をリストから選んでください（未／済／対象外）。
...

Sheet 01_Windows導入
B1: 01 Java・JMeter の入手とインストール（Windows 11）
B2: Windows 11 の端末に Java と JMeter を導入し、起動を確認して初期設定を行います。所要時間の目安は 30～60 分です。 | F2: ▲ 目次へ戻る
B4: 1. 導入の全体像
B6: ① | C6: Java（JDK）をインストールする（JMeter は Java で動くため必須）
B7: ② | C7: JMeter（apache-jmeter-5.6.3.zip）を公式サイトからダウンロードする
B8: ③ | C8: ダウンロードしたファイルが壊れていないか、ハッシュ値で確認する
B9: ④ | C9: C:\jmeter に展開し、作業用フォルダ C:\work\jmeter を作る
B10: ⑤ | C10: JMeter を起動して画面が表示されることを確認する
B11: ⑥ | C11: 初期設定（見た目・設定ファイル・プロキシ）を行う
B12: ⑦ | C12: 必要な場合のみ Plugins Manager（拡張機能の管理ツール）を導入する
B14: 用意するもの
B16: 名称 | D16: 用途 | F16: 入手先・備考
B17: Java（JDK）17 または 21 | D17: JMeter を動かすために必須。JMeter 5.6.3 は Java 8 以上で動作するが、長期サポート（LTS）版の 17 または 21 を推奨。実行サーバと同じメジャーバージョンにそろえる。 | F17: Eclipse Temurin（https://adoptium.net/）、Amazon Corretto（https://aws.amazon.com/corretto/）など
B18: Apache JMeter 5.6.3（zip） | D18: JMeter 本体 | F18: https://jmeter.apache.org/download_jmeter.cgi
B19: 作業フォルダ | D19: シナリオ・設定・結果の置き場所 | F19: C:\work\jmeter（本ガイドの例）
B20: テキストエディタ | D20: 設定ファイル（.properties）や起動用ファイル（.bat）の編集 | F20: メモ帳、または Visual Studio Code
B22: 注意 | C22: Oracle 社の JDK（Oracle JDK）は、利用条件によって有償ライセンスが必要になる場合があります。会社の規定を確認し、特に指定がなければ無償で使える OpenJDK 系（Eclipse Temurin、Amazon Corretto など）を使用してください。
B25: 2. Java のインストール
B28: 2-1. Java が入っているか確認する
B30: No. | C30: 手順 | D30: 操作内容（詳しい手順） | E30: 入力値・設定値 | F30: 確認ポイント・補足
B31: 1 | C31: PowerShell を開く | D31: スタートボタンを右クリックし、［ターミナル］（または［Windows PowerShell］）をクリックします。 | F31: 文字を入力できる画面（PowerShell）が開きます。
B32: 2 | C32: バージョンを確認 | D32: 下のコマンドを入力して Enter キーを押します。 | E32: java -version | F32: 「openjdk version "21.0.x"」のように表示されれば導入済みです。17 以上なら 2-4 に進みます。
B33: 3 | C33: 未導入の場合 | D33: 「java : 用語 'java' は、コマンドレット、関数、スクリプト ファイル、または操作可能なプログラムの名前として認識されません。」と表示されたら、Java は入っていません。 | F33: 2-2 に進みます。
C35: ▼ 表示例（バージョン番号は環境により異なります）
C36: PS C:\Users\user> java -version
C37: openjdk version "21.0.8" 2025-07-15 LTS
C38: OpenJDK Runtime Environment Temurin-21.0.8+9 (build 21.0.8+9-LTS)
C39: OpenJDK 64-Bit Server VM Temurin-21.0.8+9 (build 21.0.8+9-LTS, mixed mode, sharing)
B41: ［ 画像貼付エリア ］ 図01-1 java -version の実行結果 撮影対象：PowerShell で java -version を実行した画面 （この枠の左上のセルを選択して Ctrl+V で貼り付け、枠内に収まるようにサイズを調整してください）
B53: 図01-1 java -version の実行結果
B56: 2-2. Java（Eclipse Temurin）をダウンロードする
B58: No. | C58: 手順 | D58: 操作内容（詳しい手順） | E58: 入力値・設定値 | F58: 確認ポイント・補足
B59: 1 | C59: 配布ページを開く | D59: ブラウザで Eclipse Temurin のリリース一覧ページを開きます。 | E59: https://adoptium.net/temurin/releases/ | F59: Amazon Corretto を使う場合は https://aws.amazon.com/corretto/ から同様に入手します。
B60: 2 | C60: 条件を選ぶ | D60: 絞り込み条件を次のように選びます：Operating System＝Windows、Architecture＝x64、Package Type＝JDK、Version＝21 - LTS（または 17 - LTS）。 | E60: Windows ／ x64 ／ JDK ／ 21 - LTS | F60: サイトの画面構成は変更されることがあります。項目名が違う場合も、同じ意味の項目を選んでください。
B61: 3 | C61: ダウンロード | D61: 一覧に表示された「.msi」のファイルをクリックしてダウンロードします。 | E61: 例：OpenJDK21U-jdk_x64_windows_hotspot_21.0.x_x.msi | F61: 管理者権限がない場合は .zip を選び、2-5 の手順で導入します。
B64: 2-3. インストールする
B66: No. | C66: 手順 | D66: 操作内容（詳しい手順） | E66: 入力値・設定値 | F66: 確認ポイント・補足
B67: 1 | C67: インストーラーを起動 | D67: ダウンロードした .msi ファイルをダブルクリックします。
B68: 2 | C68: 画面を進める | D68: ［Next］で進み、使用許諾の画面では内容を確認して同意します。 | E68: ［Next］
B69: 3 | C69: JAVA_HOME を有効にする | D69: 「Custom Setup」画面で「Set JAVA_HOME variable」の左のアイコンをクリックし、「Will be installed on local hard drive」を選びます。 | E69: Set JAVA_HOME variable ＝ Will be installed on local hard drive | F69: 既定では無効になっているため、必ず有効にします。「Add to PATH」は最初から有効です。
...

Sheet 02_画面の基本
B1: 02 JMeter の画面と基本操作
B2: シナリオ作成の前に、画面の構成、テスト要素の種類、適用範囲（スコープ）と実行順序のルールを理解します。 | F2: ▲ 目次へ戻る
B4: 1. 画面の構成
B6: ［ 画像貼付エリア ］ 図02-1 JMeter のメイン画面（各部の名称） 撮影対象：JMeter の画面全体。下表の①～⑤の位置に番号を書き入れると分かりやすい （この枠の左上のセルを選択して Ctrl+V で貼り付け、枠内に収まるようにサイズを調整してください）
B30: 図02-1 JMeter のメイン画面（各部の名称）
B32: 番号 | C32: 名称 | D32: 説明
B33: ① | C33: メニューバー | D33: ［File］［Edit］［Search］［Run］［Options］［Tools］［Help］のメニューです。
B34: ② | C34: ツールバー | D34: よく使う操作（新規作成・保存・実行開始・停止・結果のクリアなど）のボタンです。
B35: ③ | C35: ツリー（テスト計画） | D35: シナリオの構造です。要素を右クリックして、子要素の追加・削除・移動を行います。
B36: ④ | C36: 設定パネル | D36: ツリーで選んだ要素の設定画面です。Name（名前）や各種設定値を入力します。
B37: ⑤ | C37: 実行状況（右上） | D37: 実行中は経過時間、警告アイコン（ログのエラー件数）、「実行中のスレッド数／全スレッド数」が表示されます。
B40: 2. よく使う操作とショートカット
B42: 操作 | D42: メニュー／ボタン | E42: ショートカット | F42: 説明
B43: 保存 | D43: ［File］→［Save］ | E43: Ctrl＋S | F43: 初回は［Save Test Plan as］で保存先とファイル名を指定します。
B44: 開く | D44: ［File］→［Open］ | E44: Ctrl＋O | F44: 既存の .jmx を開きます。
B45: 実行開始 | D45: ［Run］→［Start］（緑の ▶） | E45: Ctrl＋R | F45: シナリオを実行します（タイマーの待ち時間も含む）。
B46: 待ち時間なしで実行 | D46: ［Run］→［Start no pauses］ | E46: Ctrl＋Shift＋N | F46: タイマーを無視して実行します。動作確認を素早く行いたいとき。
B47: 停止（即時） | D47: ［Run］→［Stop］（赤の ■） | E47: Ctrl＋.（ピリオド） | F47: 実行中のリクエストも中断してすぐに止めます。
B48: 停止（終了処理付き） | D48: ［Run］→［Shutdown］ | E48: Ctrl＋,（カンマ） | F48: 新しいリクエストを止め、実行中のリクエストが終わるのを待って止めます。
B49: 結果のクリア | D49: ［Run］→［Clear］ | E49: Ctrl＋Shift＋E | F49: 選択中のリスナーの結果を消します。
B50: 全結果のクリア | D50: ［Run］→［Clear All］ | E50: Ctrl＋E | F50: すべてのリスナーの結果を消します。再実行の前に行います。
B51: 有効／無効の切替 | D51: 右クリック →［Toggle］ | E51: Ctrl＋T | F51: 要素を一時的に無効にします（グレー表示になり実行されない）。
B52: 複製 | D52: 右クリック →［Duplicate］ | E52: Ctrl＋Shift＋C | F52: 選択した要素を、子要素ごとすぐ下に複製します。
B53: 検索 | D53: ［Search］→［Search］ | E53: Ctrl＋F | F53: 要素名や設定値を検索します。
B54: 関数ヘルパー | D54: ［Tools］→［Function Helper Dialog］ | E54: Ctrl＋Shift＋F1 | F54: 関数（${__P(…)} など）の書き方を確認・テストできます。
B56: 参考 | C56: ツリーで要素を選んだ状態で Ctrl＋数字キーを押すと、よく使う要素をすぐに子要素として追加できます（Ctrl＋0：Thread Group、Ctrl＋1：HTTP Request、Ctrl＋2：Regular Expression Extractor、Ctrl＋3：Response Assertion、Ctrl＋4：Constant Timer、Ctrl＋6：JSR223 PostProcessor、Ctrl＋7：JSR223 PreProcessor、Ctrl＋8：Debug Sampler、Ctrl＋9：View Results Tree）。
B59: 3. テスト要素の種類
B61: JMeter のシナリオは、次の種類の「テスト要素」をツリー状に組み合わせて作ります。要素は、親にしたい要素を右クリック →［Add］→ 種類 → 要素名 の順で追加します。
B62: 種類（英語表示） | D62: 役割（ひとことで） | E62: 代表的な要素 | F62: 主な置き場所
B63: Test Plan | D63: シナリオ全体の入れ物。共通の変数も定義できる | E63: Test Plan | F63: ツリーの一番上（1つだけ）
B64: Threads (Users) | D64: 仮想ユーザー（スレッド）の人数・起動のしかた・繰り返し回数を決める | E64: Thread Group、setUp Thread Group、tearDown Thread Group | F64: Test Plan の直下
B65: Sampler | D65: 実際にリクエストを送る | E65: HTTP Request、Debug Sampler、JSR223 Sampler、Flow Control Action | F65: スレッドグループや Logic Controller の下
B66: Logic Controller | D66: サンプラーの実行順・回数・条件を制御する | E66: Transaction Controller、If Controller、Loop Controller、Once Only Controller | F66: スレッドグループの下
B67: Config Element | D67: 共通の設定・ヘッダー・試験データ・変数を与える | E67: HTTP Request Defaults、HTTP Header Manager、CSV Data Set Config、User Defined Variables | F67: 適用したい範囲の階層
B68: Pre Processors | D68: サンプラーの実行直前に処理する（値の生成など） | E68: JSR223 PreProcessor、User Parameters | F68: 対象サンプラーの子
B69: Post Processors | D69: サンプラーの実行直後に処理する（レスポンスから値を取り出すなど） | E69: Regular Expression Extractor、JSON Extractor、JSR223 PostProcessor | F69: 対象サンプラーの子
B70: Assertions | D70: レスポンスが正しいか検証する（NG ならエラーとして記録） | E70: Response Assertion、JSON Assertion、Duration Assertion | F70: 対象サンプラーの子
B71: Timer | D71: リクエストの前に待ち時間（思考時間）を入れる | E71: Constant Timer、Uniform Random Timer、Constant Throughput Timer | F71: 適用したい範囲の階層
B72: Listener | D72: 結果を表示・保存する | E72: View Results Tree、Summary Report、Aggregate Report | F72: Test Plan の直下（全体を対象）
B75: 4. 適用範囲（スコープ）のルール
...

Sheet 03_機能一覧
B1: 03 JMeter で使える主な機能と追加方法
B2: よく使うテスト要素・関数・メニュー機能・プラグインの一覧です。「本ガイド」列の ◎ は本ガイドのシナリオで使用、○ は推奨、△ は必要に応じて使用します。 | F2: ▲ 目次へ戻る
B4: 1. 主なテスト要素と追加方法
B6: 「追加方法」は、親要素を右クリックしてからのメニューのたどり方です。例：［Add］→［Sampler］→［HTTP Request］
B7: 要素名（英語表示） | D7: できること | E7: 追加方法 | F7: 本ガイド
B8: Threads (Users)：スレッドグループ（Test Plan を右クリック）
B9: Thread Group | D9: 仮想ユーザー数・Ramp-up・繰り返し回数・実行時間を指定する基本のスレッドグループ | E9: ［Add］→［Threads (Users)］→［Thread Group］ | F9: ◎ 本体（TG01_API）
B10: setUp Thread Group | D10: 通常のスレッドグループより前に実行される（トークン取得・データ準備） | E10: ［Add］→［Threads (Users)］→［setUp Thread Group］ | F10: ◎ トークン取得
B11: tearDown Thread Group | D11: 通常のスレッドグループの後に実行される（後片付け） | E11: ［Add］→［Threads (Users)］→［tearDown Thread Group］ | F11: △
B12: Open Model Thread Group | D12: 到着率（例：毎秒10件）で負荷を指定する新しい方式（JMeter 5.5 以降） | E12: ［Add］→［Threads (Users)］→［Open Model Thread Group］ | F12: △ 上級者向け
B13: Sampler：リクエストを送る（スレッドグループ等を右クリック）
B14: HTTP Request | D14: HTTP／HTTPS のリクエストを送る | E14: ［Add］→［Sampler］→［HTTP Request］ | F14: ◎
B15: Debug Sampler | D15: 変数・プロパティの値を結果に表示する（動作確認用） | E15: ［Add］→［Sampler］→［Debug Sampler］ | F15: ○ GUI 確認時のみ（負荷試験では無効化）
B16: JSR223 Sampler | D16: Groovy スクリプトを実行し、結果を記録する | E16: ［Add］→［Sampler］→［JSR223 Sampler］ | F16: △
B17: Flow Control Action | D17: 一時停止・スレッド停止などの制御を行う | E17: ［Add］→［Sampler］→［Flow Control Action］ | F17: △
B18: Logic Controller：実行の順番・回数・条件を制御
B19: Transaction Controller | D19: 複数のリクエストを1つの業務処理としてまとめて集計する | E19: ［Add］→［Logic Controller］→［Transaction Controller］ | F19: ○
B20: Once Only Controller | D20: 各スレッドで最初の1回だけ配下を実行する | E20: ［Add］→［Logic Controller］→［Once Only Controller］ | F20: △ スレッドごとのトークン取得
B21: If Controller | D21: 条件が成り立つときだけ配下を実行する | E21: ［Add］→［Logic Controller］→［If Controller］ | F21: △
B22: Loop Controller | D22: 配下を指定回数繰り返す | E22: ［Add］→［Logic Controller］→［Loop Controller］ | F22: △
B23: Runtime Controller | D23: 指定した秒数の間だけ配下を繰り返す | E23: ［Add］→［Logic Controller］→［Runtime Controller］ | F23: △
B24: Throughput Controller | D24: 配下の実行割合（％）や回数を制御する（業務の比率を再現） | E24: ［Add］→［Logic Controller］→［Throughput Controller］ | F24: △
B25: Simple Controller | D25: 整理用のフォルダ（動作には影響しない） | E25: ［Add］→［Logic Controller］→［Simple Controller］ | F25: ○
B26: Config Element：共通設定・ヘッダー・データ
B27: HTTP Request Defaults | D27: プロトコル・ホスト名・タイムアウト等の既定値をまとめて設定 | E27: ［Add］→［Config Element］→［HTTP Request Defaults］ | F27: ◎
B28: HTTP Header Manager | D28: リクエストヘッダー（Authorization、X-API-ID 等）を付ける | E28: ［Add］→［Config Element］→［HTTP Header Manager］ | F28: ◎
B29: User Defined Variables | D29: 変数を定義する（Test Plan の画面にも同じ欄がある） | E29: ［Add］→［Config Element］→［User Defined Variables］ | F29: ◎（Test Plan の画面で定義）
B30: CSV Data Set Config | D30: CSV ファイルから1行ずつ値を読み込み、変数に入れる | E30: ［Add］→［Config Element］→［CSV Data Set Config］ | F30: ○ 試験データの差し替え
B31: HTTP Cookie Manager | D31: Cookie を自動で保持・送信する（画面系の試験では必須） | E31: ［Add］→［Config Element］→［HTTP Cookie Manager］ | F31: △
B32: Counter | D32: 連番を作る | E32: ［Add］→［Config Element］→［Counter］ | F32: △
B33: Random Variable | D33: 指定範囲の乱数を作る | E33: ［Add］→［Config Element］→［Random Variable］ | F33: △
B34: DNS Cache Manager | D34: 名前解決の制御（負荷分散先の偏り対策） | E34: ［Add］→［Config Element］→［DNS Cache Manager］ | F34: △
B35: Pre Processors：前処理（サンプラーを右クリック）
B36: JSR223 PreProcessor | D36: リクエスト前に Groovy で値を作る（Base64・日時・署名など） | E36: ［Add］→［Pre Processors］→［JSR223 PreProcessor］ | F36: ◎ Base64 の作成
B37: User Parameters | D37: スレッドごとに異なる値を割り当てる | E37: ［Add］→［Pre Processors］→［User Parameters］ | F37: △
B38: Post Processors：後処理（サンプラーを右クリック）
B39: Regular Expression Extractor | D39: 正規表現でレスポンスから値を取り出し、変数に入れる | E39: ［Add］→［Post Processors］→［Regular Expression Extractor］ | F39: ◎ トークンの取り出し
B40: JSON Extractor | D40: JSONPath（例：$.access_token）で値を取り出す | E40: ［Add］→［Post Processors］→［JSON Extractor］ | F40: ○
B41: Boundary Extractor | D41: 左右の文字列に挟まれた部分を取り出す（正規表現不要） | E41: ［Add］→［Post Processors］→［Boundary Extractor］ | F41: △
B42: JSR223 PostProcessor | D42: 取り出した値の加工、プロパティへの保存など | E42: ［Add］→［Post Processors］→［JSR223 PostProcessor］ | F42: ◎ トークンの共有
...

Sheet 04_シナリオ作成
B1: 04 シナリオの作成（Cognito トークン取得 → API Gateway 呼び出し）
B2: Cognito でアクセストークンを取得し、そのトークンと APIキーをヘッダーに付けて API Gateway の API を呼び出すシナリオを、1ステップずつ作ります。JMeter の標準機能だけを使います（プラグイン不要）。 | F2: ▲ 目次へ戻る
B4: 1. これから作るシナリオの全体像
B6: 最初に完成形を確認します。上から順に、①setUp でトークンを1回だけ取得 → ②プロパティに保存して全スレッドで共有 → ③本体のスレッドグループで API を繰り返し呼び出す、という流れです。
B7: ツリー（要素の種類：名前） | E7: 役割 | F7: 種類
B8: Test Plan：API_LoadTest | E8: 共通の変数（接続先・ID 等）を定義する | F8: Test Plan
B9: ├─ setUp Thread Group：setUp_Token | E9: 本体より前に1回だけ実行（1スレッド×1回） | F9: setUp Thread Group
B10: │ └─ HTTP Request：T01_Cognito_Token | E10: POST /oauth2/token でトークンを取得 | F10: Sampler
B11: │ ├─ HTTP Header Manager：HDR_Token | E11: Content-Type と Authorization: Basic … | F11: Config Element
B12: │ ├─ JSR223 PreProcessor：PRE_BasicAuth | E12: client_id:client_secret を Base64 にする | F12: Pre Processor
B13: │ ├─ Regular Expression Extractor：EXT_AccessToken | E13: レスポンスから access_token を取り出す | F13: Post Processor
B14: │ ├─ JSR223 PostProcessor：POST_SaveToken | E14: 取り出したトークンをプロパティに保存 | F14: Post Processor
B15: │ ├─ Response Assertion：AST_Token_Code | E15: ステータスコード 200 を確認 | F15: Assertion
B16: │ └─ Response Assertion：AST_Token_Body | E16: 本文に access_token があるか確認 | F16: Assertion
B17: ├─ Thread Group：TG01_API | E17: 本体。スレッド数等は実行時に外から指定 | F17: Thread Group
B18: │ ├─ HTTP Request Defaults：DEF_API | E18: API Gateway のホスト名・タイムアウト | F18: Config Element
... B28: └─ Aggregate Report | E28: パーセンタイル付きの集計表 | F28: Listener
B30: ［ 画像貼付エリア ］ 図04-1 完成したシナリオのツリー 撮影対象：すべての要素を追加し終えたツリー全体（左側のツリー部分） （この枠の左上のセルを選択して Ctrl+V で貼り付け、枠内に収まるようにサイズを調整してください）
B54: 図04-1 完成したシナリオのツリー
B56: ポイント | C56: 要素の名前（Name）は英数字で付けます（例：T01_Cognito_Token）。結果ファイル・HTML レポート・Linux の画面・Excel で文字化けや扱いにくさを防ぐためです。日本語の説明は各要素の［Comments］欄に書きます。先頭の番号（T01、A01…）は、レポートで並べたときに順番どおりに表示させる工夫です。
B59: 2. 接続情報を別ファイルに分ける（env_stg.properties）
B61: 接続先やシークレットは、シナリオ（.jmx）に直接書かず、別の設定ファイル（properties ファイル）に分けます。理由は次のとおりです。
B62: ・ | C62: シークレットの漏えいを防ぐ：.jmx はチームで共有したり、構成管理ツールに登録したりするため、シークレットを書くと漏えいにつながります。
B63: ・ | C63: 環境の切り替えが簡単：ステージング用（env_stg）と本番相当用（env_prd）などのファイルを差し替えるだけで、同じ .jmx を使い回せます。
B64: ・ | C64: GUI と CLI で同じ .jmx が使える：端末では 1 ユーザー、実行サーバでは 50 ユーザーのように、実行時の指定だけで負荷を変えられます。
B65: No. | C65: 手順 | D65: 操作内容（詳しい手順） | E65: 入力値・設定値 | F65: 確認ポイント・補足
B66: 1 | C66: メモ帳を開く | D66: スタート → メモ帳 を開き、下のコードを貼り付けます。
B67: 2 | C67: 値を書き換える | D67: 00_全体像と準備 の「接続情報の記入表」を見ながら、各行の「=」の右側を現場の値に書き換えます。 | F67: client.secret と api.key は、安全な場所で管理している値を入力します。
B68: 3 | C68: 保存 | D68: ［ファイル］→［名前を付けて保存］→ ファイルの種類＝「すべてのファイル」、文字コード＝「UTF-8」で保存します。 | E68: C:\work\jmeter\props\env_stg.properties | F68: ファイルの種類を「テキスト文書」のままにすると、env_stg.properties.txt になってしまいます。
C70: ▼ C:\work\jmeter\props\env_stg.properties（値はダミー。現場の値に置き換える）
C71: # ===== env_stg.properties : staging environment =====
C72: # ASCII characters only (no Japanese)
C73: cognito.host=example-auth.auth.ap-northeast-1.amazoncognito.com
C74: scope=example-api/read
C75: client.id=1example23456789
C76: client.secret=CHANGE_ME
C77: api.host=abcde12345.execute-api.ap-northeast-1.amazonaws.com
C78: api.stage=stg
C79: api.key=CHANGE_ME
C80: # --- load settings (GUI default: 1 user x 1 loop) ---
...

Sheet 05_正規表現抽出
B1: 05 正規表現抽出（Regular Expression Extractor）の使い方
B2: レスポンスから必要な値を取り出す「正規表現抽出」の設定項目、正規表現の組み立て方、動作確認のしかた、うまくいかないときの対処をまとめます。 | F2: ▲ 目次へ戻る
B4: 1. 正規表現抽出とは
B6: Regular Expression Extractor（正規表現抽出）は、サーバから返ってきたレスポンスの中から、「この形の文字列」というパターン（正規表現）に一致する部分を探し、その一部を変数に入れる機能です。取り出した値は、後続のリクエストで ${変数名} として使えます。本ガイドでは、Cognito のレスポンスからアクセストークンを取り出すのに使います。
C7: ▼ 処理のイメージ
C8: ① T01_Cognito_Token を送信
C9: ② レスポンス：{"access_token":"eyJraWQi...","expires_in":3600,"token_type":"Bearer"}
C10: ③ 正規表現抽出で「eyJraWQi...」の部分だけを取り出し、変数 ACCESS_TOKEN に入れる
C11: ④ 後続のリクエストのヘッダーで Authorization: Bearer ${ACCESS_TOKEN} のように使う
B14: 2. 設定項目の意味
B16: 設定項目（英語表示） | D16: 設定例 | E16: 意味・選び方
B17: Name | D17: EXT_AccessToken | E17: 要素の名前です。
B18: Apply to: | D18: Main sample only | E18: どの結果を対象にするか。Main sample and sub-samples（本体と子）／Main sample only（本体のみ）／Sub-samples only（子のみ）／JMeter Variable Name to use（変数の値を対象）。API の試験では Main sample only を選びます。
B19: Field to check | D19: Body | E19: レスポンスのどこを探すか。Body（本文）／Body (unescaped)（HTML の特殊文字を戻した本文）／Body as a Document（PDF 等の文書の文字）／Response Headers（応答ヘッダー）／Request Headers（要求ヘッダー）／URL／Response Code（ステータスコード）／Response Message。
B20: Name of created variable | D20: ACCESS_TOKEN | E20: 取り出した値を入れる変数名。${ACCESS_TOKEN} で参照します。
B21: Regular Expression | D21: "access_token"\s*:\s*"([^"]+)" | E21: 探すパターン。取り出したい部分を ( ) で囲みます（3章で詳しく説明）。
B22: Template ($i$ where i is capturing group number, starts at 1) | D22: $1$ | E22: 何番目の ( ) を使うか。$1$＝1番目、$2$＝2番目、$0$＝一致した全体。$1$-$2$ のように組み合わせることもできます。
B23: Match No. (0 for Random) | D23: 1 | E23: 一致が複数あるとき何番目を使うか。1＝最初、2＝2番目、0＝ランダム、-1＝すべて（変数名_1, 変数名_2 …と、件数を表す 変数名_matchNr が作られる）。
B24: Default Value | D24: ACCESS_TOKEN_NOT_FOUND | E24: 一致しなかったときに入る値。空欄にせず、目印になる文字列を入れておくと原因調査が楽になります。
B25: Use empty default value | D25: オフ | E25: オンにすると、一致しなかったときに空の文字列を入れます。
B28: 3. 正規表現の組み立て方（アクセストークンの例）
B30: レスポンス {"access_token":"eyJraWQi...","expires_in":3600,"token_type":"Bearer"} から eyJraWQi... の部分を取り出す正規表現は、次のように部品を順番につないで作ります。
C31: ▼ 完成した正規表現
C32: "access_token"\s*:\s*"([^"]+)"
B34: 参考 | C34: このブックのフォントでは「\」（バックスラッシュ）が「¥」の形で表示されます。正規表現の「¥s」「¥d」は、JMeter には「\s」「\d」（半角のバックスラッシュ）として入力します。セルからコピーして貼り付ければ、正しい文字になります。
B36: 部品 | D36: 意味 | E36: この例で一致する文字
B37: "access_token" | D37: 文字列 "access_token"（ダブルクォートを含む）にそのまま一致 | E37: "access_token"
B38: \s* | D38: 空白（スペース・タブ・改行）が 0 文字以上。JSON が整形されていてもいなくても一致させるため | E38: （なし）
B39: : | D39: コロン | E39: :
B40: \s* | D40: 空白が 0 文字以上 | E40: （なし）
B41: " | D41: 値の始まりのダブルクォート | E41: "
B42: ([^"]+) | D42: 「ダブルクォート以外の文字」が1文字以上続く部分。( ) で囲んだので、ここが取り出される（グループ1） | E42: eyJraWQi...
B43: " | D43: 値の終わりのダブルクォート | E43: "
B45: ポイント | C45: [^"]+ は「次のダブルクォートの手前まで」を表す定番の書き方です。.+ （何でも1文字以上）を使うと、行の最後のダブルクォートまで一致してしまい、余計な文字まで取れてしまいます（「最長一致」と呼ばれる動き）。
B48: 4. よく使う記号
B50: 記号 | D50: 意味 | E50: 例
B51: . | D51: 任意の1文字（改行以外） | E51: a.c → abc、a1c に一致
B52: * | D52: 直前の文字の 0 回以上の繰り返し | E52: ab* → a、ab、abbb に一致
B53: + | D53: 直前の文字の 1 回以上の繰り返し | E53: \d+ → 1、123 に一致
B54: ? | D54: 直前の文字が 0 回か 1 回。「*?」「+?」の形では最短一致 | E54: .+? → できるだけ短く一致
...

Sheet 06_GUI実行
B1: 06 GUI での動作確認（1ユーザーでの実行）
B2: 作成したシナリオを JMeter の画面で実行し、トークン取得・ヘッダー・API 応答が正しいことを確認します。負荷をかける試験は 12（CLI）で行います。 | F2: ▲ 目次へ戻る
B4: 1. GUI 実行の目的
B6: GUI での実行は、「シナリオが正しく動くか」を確かめるためのものです。1ユーザー・1周で実行し、全リクエストが成功すること、送ったヘッダーや本文が意図どおりであることを確認します。ここで問題をすべて解消してから実行サーバへ転送すると、本番の試験で失敗するリスクを大きく減らせます。
B8: 2. 実行前のチェック
B10: No. | C10: 確認項目 | E10: 確認方法 | F10: チェック
B11: 1 | C11: start_jmeter_stg.bat から起動した（接続情報ファイルを読み込んでいる） | E11: 起動方法を確認 | F11: 未
B12: 2 | C12: threads=1、loops=1 になっている（GUI 確認用の値） | E12: env_stg.properties を確認 | F12: 未
B13: 3 | C13: View Results Tree が有効（グレーになっていない） | E13: ツリーを確認 | F13: 未
B14: 4 | C14: シナリオを保存した | E14: Ctrl＋S | F14: 未
B15: 5 | C15: 端末から Cognito・API Gateway に接続できる（プロキシ設定を含む） | E15: 04 の 7章の curl で確認 | F15: 未
B16: 6 | C16: 試験対象の担当者に、GUI での疎通確認を行うことを伝えた | E16: 連絡済みか確認 | F16: 未
B19: 3. 実行の手順
B21: No. | C21: 手順 | D21: 操作内容（詳しい手順） | E21: 入力値・設定値 | F21: 確認ポイント・補足
B22: 1 | C22: 結果をクリア | D22: メニュー［Run］→［Clear All］をクリックします（ツールバーのボタンでも可）。 | E22: Ctrl＋E | F22: 前回の結果が残っていると見分けにくいためです。
B23: 2 | C23: 実行開始 | D23: ツールバーの緑の ▶（Start）をクリックします。 | E23: Ctrl＋R | F23: 保存を確認するダイアログが出たら［Yes］で保存します。
B24: 3 | C24: 実行状況の確認 | D24: 画面右上に経過時間と「実行中のスレッド数／全スレッド数」が表示されます。 | F24: 終了すると実行中のスレッド数が 0 に戻ります。
B25: 4 | C25: 結果の一覧を開く | D25: ツリーの［View Results Tree］をクリックします。
B26: 5 | C26: 成功・失敗を見る | D26: 左側にリクエスト名が実行順に並びます。緑のアイコン＝成功、赤のアイコン＝失敗です。 | F26: T01_Cognito_Token、A01_GET_items、A02_POST_orders の3件がすべて緑なら成功です。
B27: 6 | C27: トークン取得を確認 | D27: T01_Cognito_Token をクリック →［Sampler result］で Response code: 200、［Response data］で access_token・expires_in・token_type があることを確認します。 | F27: ［Request］→［Request Headers］に Authorization: Basic … が付いていることも確認します。
B28: 7 | C28: ヘッダーを確認 | D28: A01_GET_items をクリック →［Request］→［Request Headers］で、X-API-ID と Authorization: Bearer eyJ… が付いていることを確認します。 | F28: Bearer TOKEN_NOT_SET になっていたら、トークンの共有に失敗しています（04 ステップ7）。
B29: 8 | C29: 本文を確認 | D29: A02_POST_orders の［Request］→［Request Body］で、${ITEM_ID} が実際の値（例：A001）に置き換わっていることを確認します。 | F29: ${ITEM_ID} という文字のまま送られていたら、抽出に失敗しています（05 の7章）。
B30: 9 | C30: 集計を確認 | D30: ［Summary Report］と［Aggregate Report］で、件数とエラー率（Error %）を確認します。 | F30: Error % が 0.00% であること。
B31: 10 | C31: ログを確認 | D31: 画面右上の黄色い三角形（警告）アイコンをクリックするか、［Options］→［Log Viewer］でログを表示します。 | F31: ERROR の行がないことを確認します。
B33: ［ 画像貼付エリア ］ 図06-1 実行中の画面 撮影対象：実行中の右上の表示（経過時間・スレッド数）が分かる画面 （この枠の左上のセルを選択して Ctrl+V で貼り付け、枠内に収まるようにサイズを調整してください）
B49: 図06-1 実行中の画面
B51: ［ 画像貼付エリア ］ 図06-2 View Results Tree：トークン取得の結果 撮影対象：T01_Cognito_Token を選び、Response data にレスポンスが表示された状態（トークンは塗りつぶす） （この枠の左上のセルを選択して Ctrl+V で貼り付け、枠内に収まるようにサイズを調整してください）
B73: 図06-2 View Results Tree：トークン取得の結果
B75: ［ 画像貼付エリア ］ 図06-3 View Results Tree：API 呼び出しのリクエストヘッダー 撮影対象：A01_GET_items の Request → Request Headers（APIキーとトークンは塗りつぶす） （この枠の左上のセルを選択して Ctrl+V で貼り付け、枠内に収まるようにサイズを調整してください）
B97: 図06-3 View Results Tree：API 呼び出しのリクエストヘッダー
B100: 4. View Results Tree の見方
B102: タブ | D102: 表示される内容 | F102: 確認すること
B103: Sampler result | D103: スレッド名、開始時刻、Load time（応答時間）、Connect Time、Latency、受信・送信サイズ、Response code、Response message など | F103: 応答時間とステータスコード
B104: Request → Request Body | D104: 送った本文 | F104: パラメータや JSON の ${…} が正しく置き換わっているか
B105: Request → Request Headers | D105: 送ったヘッダー | F105: Authorization、X-API-ID、Content-Type の値
B106: Response data → Response Body | D106: 受け取った本文 | F106: 期待どおりの内容か。エラーの場合はエラーメッセージ
B107: Response data → Response headers | D107: 受け取ったヘッダー | F107: x-amzn-RequestId（AWS 側の調査で使う識別番号）など
B109: 参考 | C109: ［Request］タブの下部には［Raw］と［HTTP］の切り替えがあります。［Raw］では［Request Body］／［Request Headers］がそのままの形で、［HTTP］ではメソッド・URL・パラメータ・ヘッダーが表の形で表示されます。
B111: Sampler result の項目 | D111: 意味
B112: Load time | D112: 応答時間（送信の直前から、応答の最後の1バイトを受け取るまで）。JTL の elapsed と同じ
...

Sheet 07_結果の見方
B1: 07 結果レポートの見方（リスナー・HTML レポート・JTL）
B2: JMeter が出す主な指標の意味と、Summary Report・Aggregate Report・HTML レポート（ダッシュボード）・結果ファイル（JTL）の見方をまとめます。 | F2: ▲ 目次へ戻る
B4: 1. 主な指標の意味
B6: 指標 | D6: 英語表示（単位） | E6: 意味 | F6: 見方のポイント
B7: サンプル数 | D7: # Samples（件） | E7: リクエストの件数 | F7: 想定した件数が出ているか
B8: 平均応答時間 | D8: Average（ms） | E8: 応答時間の平均 | F8: 一部の極端に遅いリクエストに引っ張られやすい
B9: 最小／最大 | D9: Min ／ Max（ms） | E9: 最も速い／最も遅い応答時間 | F9: Max は1件だけの外れ値のことが多い。参考程度に見る
B10: 中央値 | D10: Median（ms） | E10: 小さい順に並べてちょうど真ん中の値（50 パーセンタイル） | F10: 典型的な利用者の体感に近い
B11: パーセンタイル | D11: 90% Line ／ 95% Line ／ 99% Line（ms） | E11: 全体のその割合が、その値以下に収まる応答時間 | F11: 目標値の判定によく使う（例：95% Line ≦ 1,000ms）
B12: 標準偏差 | D12: Std. Dev.（ms） | E12: 応答時間のばらつきの大きさ | F12: 大きいほど応答が不安定
B13: エラー率 | D13: Error %（%） | E13: 失敗したリクエストの割合（アサーションの NG も含む） | F13: 0% が基本
B14: スループット | D14: Throughput（件/秒） | E14: 単位時間あたりに処理した件数 | F14: TPS とも呼ぶ。画面によっては /min（件/分）で表示される
B15: 受信量／送信量 | D15: Received KB/sec ／ Sent KB/sec（KB/秒） | E15: 1秒あたりのデータ量 | F15: ネットワークの負荷の目安
B16: 平均サイズ | D16: Avg. Bytes（バイト） | E16: 1件あたりの平均受信サイズ
B17: レイテンシ | D17: Latency（ms） | E17: 送信の直前から最初の1バイトを受け取るまで | F17: サーバの処理時間の目安
B18: 接続時間 | D18: Connect Time（ms） | E18: TCP 接続＋TLS の準備にかかった時間 | F18: 大きい場合は接続の作り直しが多い
B21: 応答時間の内訳（3つの時間の関係）
B23: 時間 | D23: 測っている区間 | F23: 関係
B24: Connect（接続時間） | D24: TCP 接続の確立 ＋ TLS（暗号化通信）の準備 | F24: 接続を使い回したときは 0
B25: Latency（レイテンシ） | D25: 送信の直前 ～ 応答の「最初」の1バイトを受け取るまで | F25: Connect を含む
B26: elapsed（応答時間・Load time） | D26: 送信の直前 ～ 応答の「最後」の1バイトを受け取るまで | F26: Latency を含む（elapsed ≧ Latency ≧ Connect）
B29: 2. Summary Report と Aggregate Report
B31: リスナー | D31: 主な列 | F31: 使い方
B32: Summary Report | D32: Label、# Samples、Average、Min、Max、Std. Dev.、Error %、Throughput、Received KB/sec、Sent KB/sec、Avg. Bytes | F32: 全体の傾向をつかむ
B33: Aggregate Report | D33: Label、# Samples、Average、Median、90% Line、95% Line、99% Line、Min、Max、Error %、Throughput、Received KB/sec、Sent KB/sec | F33: パーセンタイルで目標値と比べる
B35: 注意 | C35: 画面の Throughput は、値の大きさに応じて「/sec」「/min」「/hour」と単位が自動で変わります。報告書に書き写すときは単位をそろえてください。
B37: 各リスナーの画面下部にある［Save Table Data］を押すと、表を CSV で保存できます（GUI で実行した分だけ）。
B38: ［ 画像貼付エリア ］ 図07-1 Aggregate Report の画面 撮影対象：GUI 実行後の Aggregate Report（ラベル別の統計） （この枠の左上のセルを選択して Ctrl+V で貼り付け、枠内に収まるようにサイズを調整してください）
B54: 図07-1 Aggregate Report の画面
B57: 3. HTML レポート（ダッシュボード）
B60: 3-1. 作り方
B62: 方法 | D62: 手順 | F62: 使う場面
B63: CLI 実行と同時に作る（推奨） | D63: jmeter コマンドに -e -o <出力フォルダ> を付ける（12 参照） | F63: 負荷試験の本番
B64: 結果ファイルから後で作る（CLI） | D64: jmeter -g result.jtl -o report_new（出力フォルダは存在しないか空であること） | F64: レポートを作り直すとき
B65: 結果ファイルから後で作る（GUI） | D65: ［Tools］→［Generate HTML report］→ Results file (csv or jtl) に結果ファイル、user.properties file に C:\jmeter\apache-jmeter-5.6.3\bin\user.properties、Output directory に空のフォルダを指定 →［Generate report］ | F65: 端末でレポートを作り直すとき
B68: 3-2. 開き方
B70: 出力フォルダの中の index.html をダブルクリックすると、ブラウザでレポートが表示されます（インターネット接続は不要です）。
B71: ［ 画像貼付エリア ］ 図07-2 HTML レポートの Dashboard 画面 撮影対象：index.html をブラウザで開いた最初の画面（APDEX・Requests Summary・Statistics） （この枠の左上のセルを選択して Ctrl+V で貼り付け、枠内に収まるようにサイズを調整してください）
B95: 図07-2 HTML レポートの Dashboard 画面
B98: 3-3. 画面の構成と確認ポイント
...

Sheet 08_確認観点
B1: 08 結果の確認観点と判定の考え方
B2: 負荷試験の結果を「何を・どこで・どう判断するか」を整理します。報告書の考察を書くときのチェックリストとしても使えます。 | F2: ▲ 目次へ戻る
B4: 1. 確認の基本的な流れ
B6: ① | C6: 試験が有効か：想定どおりのスレッド数・時間・件数で負荷がかかったか
B7: ② | C7: エラーの有無と種類：エラー率と、どのエラーがいつ出たか
B8: ③ | C8: 応答時間：パーセンタイル（90/95/99%）が目標値の範囲内か
B9: ④ | C9: スループット：目標の処理件数（件/秒）を満たしたか
B10: ⑤ | C10: 時系列の安定性：時間とともに悪化したり、不安定になったりしていないか
B11: ⑥ | C11: 原因の考察：サーバ側・負荷生成側のリソースと突き合わせて、限界点やボトルネックを考える
B13: 2. 確認観点の一覧
B15: No. | C15: 観点 | D15: 確認方法（どこを見るか） | E15: 判断の目安（例） | F15: NG のときに疑うこと
B16: 1 | C16: 想定どおりの負荷 | D16: Active Threads Over Time、JTL の allThreads、サンプル数 | E16: 設定したスレッド数に到達し、試験中は維持されている | F16: Ramp-up の設定誤り、負荷生成サーバの性能不足
B17: 2 | C17: 試験時間 | D17: HTML レポートの Test and Report information | E17: 予定どおり（例：600 秒） | F17: エラーによる停止（Stop Test）、SSH 切断
B18: 3 | C18: エラー率 | D18: Statistics の Error %、Errors 表 | E18: 0%（許容値は試験計画で合意。例：0.1% 未満） | F18: 下の No.4 のエラー別の原因
B19: 4 | C19: エラーの種類 | D19: Errors／Top 5 Errors、Codes Per Second | E19: ― | F19: 401：トークン期限切れ・未設定／403：APIキー・WAF／429：流量制限／5xx：バックエンド／Non HTTP：ネットワーク・タイムアウト・負荷生成側
B20: 5 | C20: 応答時間 | D20: 90／95／99 パーセンタイル（平均だけで判断しない） | E20: 目標値以内（例：95% ≦ 1,000ms） | F20: DB・外部 API の待ち、Lambda のコールドスタート
B21: 6 | C21: スループット | D21: Throughput、Total Transactions Per Second | E21: 目標値以上（例：50 件/秒以上） | F21: スレッド数不足・思考時間が長すぎる（JMeter 側）、処理の限界（サーバ側）
B22: 7 | C22: 時系列の安定性 | D22: Response Times Over Time | E22: 定常状態の区間で横ばい | F22: 時間とともに悪化＝リソースの解放漏れ、処理待ちの滞留
B23: 8 | C23: 負荷と応答時間の関係 | D23: Time Vs Threads、Response Time Vs Request | E23: スレッド数の増加に比例してスループットが増える | F23: スループットが頭打ちで応答時間が悪化＝ボトルネック（限界点）に到達
B24: 9 | C24: ばらつき | D24: Std. Dev.、Max と 99% Line の差 | E24: 極端な外れ値がない | F24: GC（メモリ整理）、オートスケーリング、スロットリング
B25: 10 | C25: 接続時間 | D25: Connect Time Over Time | E25: 接続の使い回しで小さい値 | F25: 接続の作り直しが多い、TLS の負荷
B26: 11 | C26: 負荷生成側の健全性 | D26: 実行サーバの CPU・メモリ（top、vmstat）、jmeter.log | E26: CPU 使用率 80% 未満、OutOfMemoryError なし | F26: 負荷生成側がボトルネック → 測定値が不正確
... B29: 14 | C29: 再現性 | D29: 同じ条件で複数回実行 | E29: 結果のぶれが小さい | F29: 外部要因（他の利用者、バッチ処理）
B32: 3. AWS 側で確認する主なメトリクス（CloudWatch）
B34: サービス | D34: メトリクス | E34: 見るポイント
B35: API Gateway | D35: Count | E35: 受け付けたリクエスト数。JMeter の件数と合っているか
B36: API Gateway | D36: Latency | E36: API Gateway がリクエストを受けてから応答するまでの時間
B37: API Gateway | D37: IntegrationLatency | E37: バックエンド（Lambda 等）の処理時間。Latency との差が API Gateway 自体の処理時間
B38: API Gateway | D38: 4XXError ／ 5XXError | E38: クライアントエラー／サーバエラーの件数
B39: Lambda | D39: Invocations ／ Duration ／ Errors ／ Throttles ／ ConcurrentExecutions | E39: 同時実行数の上限到達（Throttles）、処理時間（Duration）の悪化
B40: Lambda | D40: （ログの Init Duration） | E40: コールドスタートによる試験開始直後の遅延
B41: DynamoDB | D41: ConsumedRead/WriteCapacityUnits ／ ThrottledRequests | E41: 読み書きの性能（キャパシティ）不足
B42: RDS ／ Aurora | D42: CPUUtilization ／ DatabaseConnections ／ ReadLatency・WriteLatency | E42: データベースのボトルネック
B43: Cognito | D43: CallCount ／ ThrottleCount | E43: トークン発行などのリクエスト数と、制限による拒否
B44: AWS WAF | D44: BlockedRequests | E44: 実行サーバの IP が遮断されていないか
B46: 注意 | C46: CloudWatch のグラフは UTC で表示されることがあります（画面右上の時刻設定でローカル時刻に切り替え可能）。JMeter の結果（JST）と時刻を合わせてから比べてください。
B49: 4. 判定（合否）の考え方
B51: ・ | C51: 目標値は試験の前に合意しておきます（例：95 パーセンタイル応答時間 ≦ 1,000ms、エラー率 ＜ 0.1%、スループット ≧ 50 件/秒）。
B52: ・ | C52: Ramp-up 中や終了間際は負荷が安定しません。開始1分後～終了1分前など「定常状態」の区間だけで評価する方法もあります。その場合は評価区間を報告書に明記します（15 の STEP7）。
B53: ・ | C53: 平均値だけで判定しません。少数の極端に遅いリクエストが隠れてしまうため、パーセンタイルを併記します。
...

Sheet 09_注意点
B1: 09 注意点（実施前・実施中・実施後）
B2: 負荷試験で失敗や事故を起こさないための注意点を、分類ごとにまとめます。実施前に必ず一読してください。 | F2: ▲ 目次へ戻る
B3: No. | C3: 注意点 | E3: 守らないと起きること | F3: 対策
B4: 実施前の合意
B5: 1 | C5: 必ず関係者の承認と事前連絡のうえで実施する | E5: 共用環境の他の利用者や監視担当に影響し、障害と誤解される | F5: 試験計画書で日時・負荷量・緊急停止の連絡先を合意する
B6: 2 | C6: 本番環境に無断で負荷をかけない | E6: 業務停止や想定外の課金につながる | F6: 試験対象の環境を明記して承認を得る
B7: 3 | C7: 登録系 API の後始末を決めておく | E7: 試験データが残り、一意制約エラーや他の試験への影響が出る | F7: 削除方法・試験用データの範囲を開発担当と取り決める
B8: AWS の制限と課金
B9: 4 | C9: API Gateway の使用量プラン（スロットリング・クォータ）を確認する | E9: 429 Too Many Requests で試験が無効になる。クォータを使い切ると、同じキーを使う他の利用者も呼べなくなる | F9: 試験用の APIキー・使用量プランを用意し、上限値を確認する
B10: 5 | C10: AWS WAF のレートベースルールや IP 制限を確認する | E10: 実行サーバの IP が遮断され 403 になる | F10: 事前にルールを確認し、必要なら許可設定を依頼する
B11: 6 | C11: Cognito のトークン取得を大量に行わない | E11: 制限（スロットリング）に達する。client_credentials のトークン発行は従量課金の対象になる場合がある | F11: トークンは setUp で1回取得して共有する（04 の6章）
B12: 7 | C12: Lambda の同時実行数の上限を確認する | E12: 同じアカウントの他システムの Lambda まで巻き込んで制限される | F12: 上限値・予約同時実行数を基盤担当に確認する
B13: 8 | C13: リクエスト数に応じて費用がかかる | E13: 想定外の費用が発生する | F13: 事前に概算し、試験時間・回数を管理する
B14: セキュリティ
B15: 9 | C15: client_secret や APIキーを .jmx・Excel に直接書かない | E15: .jmx の共有や構成管理への登録で漏えいする | F15: properties ファイルで渡し、実行サーバでは権限を 600 にする
B16: 10 | C16: 画面キャプチャ・ログ・報告書にトークンやキーを載せない | E16: Authorization ヘッダーなどが写り込む | F16: 貼り付ける前に塗りつぶす
B17: 11 | C17: トークンを外部の Web サイト（JWT の解析サイト等）に貼り付けない | E17: 第三者にトークンが渡る | F17: 必要な場合は社内で許可された方法で確認する
B18: JMeter
B19: 12 | C19: GUI で負荷試験をしない | E19: 画面の描画が CPU・メモリを消費して測定値が不正確になり、JMeter が固まる | F19: GUI は作成と確認のみ。本番は CLI で実行
B20: 13 | C20: 負荷試験では View Results Tree・Debug Sampler を無効にする | E20: メモリを大量に使う。結果にシークレットが残る | F20: 転送前に Toggle で無効化する
B21: 14 | C21: 端末と実行サーバで JMeter・Java・プラグインの版をそろえる | E21: .jmx を読み込めない、動作が変わる | F21: 版を報告書に記録する
B22: 15 | C22: 結果ファイル（-l）は、既にあると追記される | E22: 前回の結果と混ざる（-e 指定時はエラーで止まる） | F22: 実行ごとに日時付きのフォルダに出力する（12）
B23: 16 | C23: -o のフォルダは空（または存在しない）であること | E23: HTML レポートを作れずエラーになる | F23: 日時付きのフォルダを使う、または -f を付ける
B24: 17 | C24: ${__P(名前)} の既定値を省略しない | E24: プロパティが無いと「1」になり、意図しない値で動く | F24: ${__P(threads,1)} のように既定値を書く
B25: 18 | C25: タイマーは範囲内のすべてのリクエストの前で動く | E25: 思考時間が想定の倍になる | F25: タイマーを置く場所を確認する（02 の4章）
B26: 19 | C26: 応答のタイムアウトを設定する | E26: 応答が返らないとスレッドが止まったままになり、負荷が出なくなる | F26: HTTP Request Defaults の Timeouts を設定する
B27: 負荷生成サーバ
B28: 20 | C28: 実行サーバの CPU・メモリ・ネットワークを監視する | E28: JMeter 側が先に限界になると、結果が不正確になる | F28: CPU 80% を超えるならスレッドを減らすか、サーバを増やす
B29: 21 | C29: JMeter のメモリ（HEAP）を適切に設定する | E29: OutOfMemoryError で試験が止まる | F29: サーバのメモリの半分程度まで（例：メモリ 4GB のサーバで -Xmx2g）
B30: 22 | C30: SSH が切れても試験が止まらないようにする | E30: 端末のスリープや回線断で試験が中断する | F30: tmux または nohup で実行する（12）
B31: ファイル・文字コード
B32: 23 | C32: Windows で作ったファイルの改行コード（CRLF） | E32: シェルスクリプトが「bad interpreter」で動かない | F32: LF で保存する。または sed -i 's/\r$//' ファイル名 で変換する
B33: 24 | C33: Linux はファイル名の大文字・小文字を区別する | E33: ファイルが見つからないエラーになる | F33: ファイル名は英小文字で統一する
B34: 25 | C34: パスに日本語・空白を使わない | E34: 文字化けやコマンドの誤動作 | F34: C:\work\jmeter のような英数字のパスにする
B35: 26 | C35: properties ファイルに日本語を書かない | E35: 文字化けして値が正しく読めない | F35: 英数字・記号だけで書く
B36: 時刻
B37: 27 | C37: JTL の timeStamp は UTC 基準のミリ秒 | E37: Excel でそのまま日時にすると9時間ずれる | F37: ＋9時間して JST に変換する（14）
B38: 28 | C38: 実行サーバの時刻同期とタイムゾーンを確認する | E38: サーバ側のログや CloudWatch と時刻を突き合わせられない | F38: timedatectl で確認する（10）
B39: ディスク
B40: 29 | C40: JTL は大きくなる（1件あたり約 150～250 バイト） | E40: ディスクがいっぱいになり、試験や OS に影響する | F40: df -h で空きを確認し、100万件なら約 200MB を見込む
...

Sheet 10_Linux準備
B1: 10 実行サーバ（Linux）の準備
B2: 負荷をかける Linux サーバに Java と JMeter を導入し、作業用フォルダや OS の設定を整えます。コマンドは SSH でログインした画面で実行します。 | F2: ▲ 目次へ戻る
B4: 1. 実行サーバの要件（目安）
B6: 項目 | D6: 推奨・目安 | E6: 確認コマンド
B7: OS | D7: Amazon Linux 2023、RHEL 8／9 系、Ubuntu 22.04／24.04 など | E7: cat /etc/os-release
B8: CPU | D8: 2コア以上（負荷の大きさに応じて増やす） | E8: nproc
B9: メモリ | D9: 4GB 以上（JMeter に 2GB ＋ OS 用） | E9: free -h
B10: ディスク | D10: 結果の保存用に 10GB 以上の空き | E10: df -h ~
B11: Java | D11: 端末と同じメジャーバージョン（17 または 21） | E11: java -version
B12: ネットワーク | D12: 試験対象に HTTPS（443）で接続できること | E12: curl -sI https://<対象のホスト名>
B13: 時刻 | D13: 時刻同期（NTP）されていること。タイムゾーンを把握しておく | E13: timedatectl
B15: ポイント | C15: 負荷生成サーバは、試験対象と同じリージョン（例：東京リージョン）に置くと、ネットワークの遅延が結果に混ざりにくくなります。
B18: 2. SSH で接続する（Windows の PowerShell から）
B21: 2-1. 直接接続する場合
C23: ▼ PowerShell（鍵ファイル・ユーザー名・IP は現場の値に置き換え）
C24: ssh -i $env:USERPROFILE\.ssh\jmeter-key.pem ec2-user@10.0.1.25
B26: 部分 | D26: 意味
B27: -i …\jmeter-key.pem | D27: ログインに使う秘密鍵ファイル（インフラ担当から受け取ったもの）
B28: ec2-user | D28: ログインするユーザー名（Amazon Linux は ec2-user、Ubuntu は ubuntu が一般的）
B29: 10.0.1.25 | D29: 実行サーバの IP アドレスまたはホスト名
B31: 初めて接続するときは「Are you sure you want to continue connecting (yes/no/[fingerprint])?」と聞かれます。表示されたフィンガープリントをインフラ担当に確認してから yes と入力します。
B33: 2-2. 踏み台サーバを経由する場合（設定ファイルを使う方法・推奨）
B35: 接続先の情報を設定ファイルに書いておくと、ssh jmeter-server のように短い名前で接続でき、ファイル転送（scp）のコマンドも短くなります。
C36: ▼ PowerShell（「新しく作成しますか？」と聞かれたら［はい］）
C37: New-Item -ItemType Directory -Force $env:USERPROFILE\.ssh | Out-Null
C38: notepad $env:USERPROFILE\.ssh\config
C40: ▼ C:\Users\<ユーザー名>\.ssh\config の内容（拡張子なし）
C41: Host bastion
C42: HostName bastion.example.co.jp
C43: User ec2-user
C44: IdentityFile ~/.ssh/bastion-key.pem
C46: Host jmeter-server
C47: HostName 10.0.1.25
C48: User ec2-user
C49: IdentityFile ~/.ssh/jmeter-key.pem
... C53: ssh jmeter-server
B55: 参考 | C55: 踏み台がない場合は、「Host bastion」の4行と「ProxyJump bastion」の行を削除します。鍵ファイルは C:\Users\<ユーザー名>\.ssh に置きます。
B58: 2-3. 鍵ファイルの権限エラーが出た場合
B60: 「WARNING: UNPROTECTED PRIVATE KEY FILE!」や「bad permissions」と表示されて接続できない場合は、鍵ファイルを本人だけが読めるように権限を変更します。
C61: ▼ PowerShell
...

Sheet 11_転送と配置
B1: 11 ファイルの転送と配置（Windows → Linux）
B2: 端末で作ったシナリオ・データ・接続情報を実行サーバへ転送し、正しく配置されたことを確認します。最後に1ユーザーで試し実行します。 | F2: ▲ 目次へ戻る
B4: 1. 転送するファイル
B6: ファイル | D6: 端末側の場所 | E6: 実行サーバ側の配置先 | F6: 備考
B7: シナリオ | D7: C:\work\jmeter\scenarios\api_loadtest.jmx | E7: ~/jmeter-work/scenarios/ | F7: View Results Tree 等を無効化して保存したもの（06 の8章）
B8: 試験データ（使う場合） | D8: C:\work\jmeter\data\items.csv | E8: ~/jmeter-work/data/ | F8: シナリオからの相対パスが端末と同じになる位置に置く
B9: 接続情報 | D9: C:\work\jmeter\props\env_stg.properties | E9: ~/jmeter-work/props/ | F9: 転送後に権限を 600 にする。負荷の値（threads 等）は実行時に指定
B10: 実行スクリプト | D10: （サーバ上で直接作成） | E10: ~/jmeter-work/scripts/run_test.sh | F10: 12 の4章の方法で作成（改行コードの問題を避けるため）
B11: プラグイン（使う場合） | D11: lib\ext・lib に追加された jar | E11: /opt/jmeter/lib/ext/、/opt/jmeter/lib/ | F11: 10 の9章を参照
B14: 2. 方法A：scp コマンドで転送する（PowerShell）
B16: Windows 11 には scp コマンドが標準で入っています。10 の 2-2 で SSH の設定ファイル（jmeter-server）を作った場合は、次のように短く書けます。
C17: ▼ PowerShell（設定ファイルを使う場合）
C18: scp C:\work\jmeter\scenarios\api_loadtest.jmx jmeter-server:/home/ec2-user/jmeter-work/scenarios/
C19: scp C:\work\jmeter\props\env_stg.properties jmeter-server:/home/ec2-user/jmeter-work/props/
C20: scp -r C:\work\jmeter\data jmeter-server:/home/ec2-user/jmeter-work/
C22: ▼ PowerShell（設定ファイルを使わない場合）
C23: scp -i $env:USERPROFILE\.ssh\jmeter-key.pem `
C24: C:\work\jmeter\scenarios\api_loadtest.jmx `
C25: ec2-user@10.0.1.25:/home/ec2-user/jmeter-work/scenarios/
B27: 部分 | D27: 意味
B28: scp 送るファイル 送り先 | D28: 左のファイルを右の場所にコピーします。送り先は「接続先:サーバ上のフォルダ」の形です。
B29: -r | D29: フォルダごとコピーします（data フォルダの中身をまとめて送る）。
B30: /home/ec2-user/… | D30: サーバ上の絶対パス。ユーザー名の部分は自分のユーザー名に合わせます（Ubuntu なら /home/ubuntu/…）。
B32: ポイント | C32: サーバ側のフォルダは「/」で始まる絶対パスで書くと確実です。「~」（ホーム）は scp では環境によって解釈されないことがあります。
B35: 3. 方法B：WinSCP（画面操作）で転送する
B37: 会社で WinSCP の利用が許可されている場合は、エクスプローラーのような画面でドラッグ＆ドロップで転送できます。
B38: No. | C38: 手順 | D38: 操作内容（詳しい手順） | E38: 入力値・設定値 | F38: 確認ポイント・補足
B39: 1 | C39: 接続先を登録 | D39: WinSCP を起動し、「ログイン」画面で［新しいサイト］を選びます。 | E39: 転送プロトコル：SFTP ホスト名：10.0.1.25 ポート番号：22 ユーザー名：ec2-user
B40: 2 | C40: 鍵を設定 | D40: ［設定］→［SSH］→［認証］→「秘密鍵」に .pem ファイルを指定します。 | E40: jmeter-key.pem | F40: PuTTY 形式（.ppk）への変換を確認されたら［OK］で変換します。
B41: 3 | C41: 踏み台の設定（必要な場合） | D41: ［設定］→［接続］→［トンネル］で踏み台サーバを指定します。
B42: 4 | C42: ログイン | D42: ［保存］してから［ログイン］します。 | F42: 初回はホスト鍵の確認が出るので、内容を確認して［はい］。
B43: 5 | C43: 転送 | D43: 左側（端末）から右側（サーバ）の ~/jmeter-work/scenarios などへドラッグ＆ドロップします。 | F43: 転送モードは「バイナリ」を推奨します（ファイルの中身を変えずに送るため）。
B45: ［ 画像貼付エリア ］ 図11-1 WinSCP のログイン画面 撮影対象：接続先（SFTP・ホスト名・ユーザー名）を入力した状態（IP 等は塗りつぶす） （この枠の左上のセルを選択して Ctrl+V で貼り付け、枠内に収まるようにサイズを調整してください）
B63: 図11-1 WinSCP のログイン画面
B65: ［ 画像貼付エリア ］ 図11-2 WinSCP でのファイル転送 撮影対象：左に端末のフォルダ、右にサーバの ~/jmeter-work を表示した状態 （この枠の左上のセルを選択して Ctrl+V で貼り付け、枠内に収まるようにサイズを調整してください）
B83: 図11-2 WinSCP でのファイル転送
B86: 4. 配置後の確認
B89: 4-1. ファイルの有無と権限
C91: ▼ Linux
C92: ls -l ~/jmeter-work/scenarios/ ~/jmeter-work/props/ ~/jmeter-work/data/
...

Sheet 12_CLI実行と監視
B1: 12 CLI での負荷試験の実行と監視
B2: jmeter コマンドの書き方（jmx・結果ファイル・ログの出力先の指定）、実行スクリプト、SSH が切れても止まらない実行方法、実行中の監視、停止方法をまとめます。 | F2: ▲ 目次へ戻る
B4: 1. コマンドの基本形
C6: ▼ 基本形
C7: jmeter -n -t <jmxファイル> -l <結果ファイル.jtl> -j <ログファイル.log> -e -o <HTMLレポートの出力先フォルダ>
C9: ▼ 具体例（行末の「\」は、次の行に続くことを表す記号）
C10: jmeter -n \
C11: -t /home/ec2-user/jmeter-work/scenarios/api_loadtest.jmx \
C12: -q /home/ec2-user/jmeter-work/props/env_stg.properties \
C13: -Jthreads=20 -Jrampup=60 -Jloops=-1 -Jduration=600 \
C14: -l /home/ec2-user/jmeter-work/results/20261001_100000/result.jtl \
C15: -j /home/ec2-user/jmeter-work/results/20261001_100000/jmeter.log \
C16: -e -o /home/ec2-user/jmeter-work/results/20261001_100000/report
B19: 2. オプションの一覧
B21: オプション | D21: 正式名 | E21: 意味 | F21: 本ガイドでの指定例
B22: -n | D22: --nongui | E22: 画面を使わない CLI モードで実行する | F22: -n
B23: -t | D23: --testfile | E23: 実行するシナリオ（.jmx） | F23: -t …/scenarios/api_loadtest.jmx
B24: -l | D24: --logfile | E24: 結果ファイル（JTL）の出力先 | F24: -l …/result.jtl
B25: -j | D25: --jmeterlogfile | E25: JMeter の実行ログの出力先（省略するとコマンドを実行したフォルダに jmeter.log） | F25: -j …/jmeter.log
B26: -e | D26: --reportatendofloadtests | E26: 試験の終了後に HTML レポートを作る | F26: -e
B27: -o | D27: --reportoutputfolder | E27: HTML レポートの出力先（存在しない、または空のフォルダ） | F27: -o …/report
B28: -J | D28: --jmeterproperty | E28: プロパティを指定する（シナリオ内の ${__P(名前,…)} に入る） | F28: -Jthreads=20
B29: -q | D29: --addprop | E29: 追加のプロパティファイルを読み込む | F29: -q …/env_stg.properties
B30: -f | D30: --forceDeleteResultFile | E30: 既存の結果ファイルとレポートフォルダを削除してから実行する | F30: （同じ名前で実行し直す場合）
B31: -g | D31: --reportonly | E31: 既存の結果ファイルから HTML レポートだけを作る | F31: -g result.jtl -o report2
B32: -L | D32: --loglevel | E32: ログの詳しさを変える | F32: -Lorg.apache.jmeter.protocol.http=DEBUG（調査時のみ）
... B34: -v | D34: --version | E34: 版を表示する | F34: jmeter -v
B35: -? | E35: オプションの一覧を表示する | F35: jmeter -?
B37: 注意 | C37: -q は -J より前に書きます。オプションは書いた順に読み込まれ、後から指定した値が優先されるため、-q のファイルに threads=1 があっても、後ろの -Jthreads=20 が使われます。
B40: 3. jmx・結果ファイル・ログの指定のしかた
B43: 3-1. jmx（シナリオ）の指定
B45: ・ | C45: 絶対パス（「/」で始まる完全な場所）で指定するのが確実です：-t /home/ec2-user/jmeter-work/scenarios/api_loadtest.jmx
B46: ・ | C46: 相対パスで指定する場合は、コマンドを実行しているフォルダが基準になります：cd ~/jmeter-work してから -t scenarios/api_loadtest.jmx
B47: ・ | C47: シナリオの中の CSV ファイルなどの相対パスは、「.jmx ファイルがあるフォルダ」が基準になります（実行したフォルダではありません）。
B48: ・ | C48: 1回の jmeter コマンドで指定できる .jmx は1つです。
B49: ・ | C49: Linux はファイル名の大文字・小文字を区別します。途中まで入力して Tab キーを押すと名前が補完され、入力ミスを防げます。
B51: 3-2. 結果ファイル（-l）・ログ（-j）・レポート（-o）の出力先
B53: オプション | D53: 出力されるもの | F53: 注意点
B54: -l result.jtl | D54: 全リクエストの結果（CSV 形式、拡張子は .jtl） | F54: 同じ名前のファイルがあると追記されます（-e を付けているとエラーで止まります）。
B55: -j jmeter.log | D55: JMeter の実行ログ（開始・終了・エラー） | F55: 省略すると、コマンドを実行したフォルダに jmeter.log が作られます。
...

Sheet 13_結果回収
B1: 13 結果の回収（Linux → Windows）
B2: 実行サーバに出力された結果一式を圧縮して端末へ転送し、展開して HTML レポートを開くまでの手順です。 | F2: ▲ 目次へ戻る
B4: 1. 回収する成果物
B6: ファイル | D6: 内容 | F6: 報告での使い道
B7: result.jtl | D7: 全リクエストの結果（CSV） | F7: Excel 分析の元データ（14・15）
B8: jmeter.log | D8: JMeter の実行ログ | F8: エラーの調査、実行条件の証跡
B9: console.log | D9: 画面に出た途中経過（summary 行） | F9: 実行経過の証跡
B10: report/ | D10: HTML レポート一式 | F10: グラフ・統計表の画面キャプチャ
B11: （任意）サーバ側メトリクス | D11: CloudWatch のグラフ・CSV | F11: 考察の根拠
B14: 2. 実行サーバで圧縮する
C16: ▼ Linux（フォルダ名は ls -lt で表示された実際の名前に置き換え）
C17: cd ~/jmeter-work/results
C18: ls -lt | head
C19: tar -czf 20261001_100000_api_loadtest_20th.tar.gz 20261001_100000_api_loadtest_20th
C20: ls -lh 20261001_100000_api_loadtest_20th.tar.gz
B22: コマンド | D22: 意味
B23: ls -lt | head | D23: 新しい順に一覧を表示し、今回のフォルダ名を確認します。
B24: tar -czf 圧縮後.tar.gz フォルダ | D24: フォルダを1つのファイル（.tar.gz）にまとめて圧縮します。
B25: ls -lh … | D25: できたファイルの大きさを確認します。
B28: 3. 端末へ転送する
C30: ▼ PowerShell（10 の 2-2 の設定ファイルを使う場合）
C31: scp jmeter-server:/home/ec2-user/jmeter-work/results/20261001_100000_api_loadtest_20th.tar.gz C:\work\jmeter\results\
C33: ▼ PowerShell（設定ファイルを使わない場合）
C34: scp -i $env:USERPROFILE\.ssh\jmeter-key.pem `
C35: ec2-user@10.0.1.25:/home/ec2-user/jmeter-work/results/20261001_100000_api_loadtest_20th.tar.gz `
C36: C:\work\jmeter\results\
B38: WinSCP を使う場合は、右側（サーバ）の tar.gz を左側（端末）の C:\work\jmeter\results へドラッグ＆ドロップします。
B40: 4. 展開して HTML レポートを開く
C42: ▼ PowerShell（Windows 11 は tar コマンドが標準で使えます）
C43: cd C:\work\jmeter\results
C44: tar -xzf .\20261001_100000_api_loadtest_20th.tar.gz
C45: Get-ChildItem .\20261001_100000_api_loadtest_20th
C46: Start-Process .\20261001_100000_api_loadtest_20th\report\index.html
B48: ［ 画像貼付エリア ］ 図13-1 回収した結果フォルダ 撮影対象：エクスプローラーで展開後のフォルダ（result.jtl・jmeter.log・report）を表示した状態 （この枠の左上のセルを選択して Ctrl+V で貼り付け、枠内に収まるようにサイズを調整してください）
B62: 図13-1 回収した結果フォルダ
B65: 5. 保管のルール（おすすめ）
B67: ・ | C67: フォルダ名は「日時_シナリオ名_スレッド数」のまま保管し、どの試験の結果か分かるようにします。
B68: ・ | C68: 元の結果ファイル（result.jtl）は書き換えません（読み取り専用にしておくと安心です）。分析は別の Excel ブックで行います。
B69: ・ | C69: 試験条件（スレッド数・Ramp-up・試験時間・JMeter と Java の版・対象環境）を、報告書（18）か同じフォルダのメモに必ず残します。
B70: ・ | C70: サーバ側メトリクス（CloudWatch の画面キャプチャ等）も、同じフォルダにまとめて保管します。
...

Sheet 14_Excel取込
B1: 14 結果ファイル（JTL）を Excel に取り込む
B2: 回収した result.jtl を、文字化けや型の崩れなく Excel に取り込む手順です。Excel for Microsoft 365（Windows）の画面で説明します。 | F2: ▲ 目次へ戻る
B4: 1. 取り込み方法の比較
B6: 方法 | D6: 手順 | F6: 評価
B7: A：Power Query で取り込む（推奨） | D7: ［データ］→［テキストまたは CSV から］で、文字コード・区切り文字・列の型を指定して取り込む | F7: ◎ 文字化けや型の崩れを防げる。次の試験結果への差し替えも簡単
B8: B：ダブルクリックで開く | D8: .jtl を .csv に名前を変えて開く | F8: × 日本語が文字化けする（UTF-8 を Shift_JIS と誤認）、timeStamp が 1.79E+12 のような指数表示になる、responseCode が数値になる
B11: 2. Power Query で取り込む手順
B13: No. | C13: 手順 | D13: 操作内容（詳しい手順） | E13: 入力値・設定値 | F13: 確認ポイント・補足
B14: 1 | C14: 分析用のブックを作る | D14: Excel を起動して［空白のブック］を開き、C:\work\jmeter\analysis に保存します。 | E14: 例：analysis_20261001_20th.xlsx | F14: 結果ファイル（result.jtl）とは別のブックで分析します。
B15: 2 | C15: 取り込みを開始 | D15: ［データ］タブ →［データの取得と変換］グループ →［テキストまたは CSV から］をクリックします。
B16: 3 | C16: ファイルを選ぶ | D16: ダイアログ右下のファイルの種類を［すべてのファイル (*.*)］に変え、回収したフォルダの result.jtl を選んで［インポート］します。 | E16: C:\work\jmeter\results\<フォルダ>\result.jtl | F16: 最初は .csv と .txt しか表示されないため、種類の変更が必要です。
B17: 4 | C17: 読み込み方を指定 | D17: プレビュー画面の上部で次のように選びます。 | E17: 元のファイル：65001 : Unicode (UTF-8) 区切り記号：コンマ データ型検出：最初の 200 行に基づく | F17: 1行目の列名（timeStamp, elapsed…）が見出しになっていることを確認します。
B18: 5 | C18: 変換画面を開く | D18: 右下の［データの変換］をクリックします（［読み込み］ではありません）。 | E18: ［データの変換］ | F18: Power Query エディターが開きます。
B19: 6 | C19: 引用符の中の改行を正しく読む | D19: 右側の［適用したステップ］の一番上の［ソース］をクリックし、画面上部の数式バーの式の最後にある QuoteStyle=QuoteStyle.None を QuoteStyle=QuoteStyle.Csv に書き換えて、Enter キーを押します（最初から QuoteStyle.Csv なら変更不要）。 | E19: QuoteStyle=QuoteStyle.Csv | F19: NG になったリクエストの行は failureMessage に改行を含みます（07 の4章）。None のままだと1件が複数の行に分かれ、表が崩れます。数式バーが見えない場合は［表示］→［数式バー］にチェックを入れます。
B20: 7 | C20: 見出しの確認 | D20: 列名が timeStamp、elapsed … になっているか確認します。Column1… になっている場合は［ホーム］→［1 行目をヘッダーとして使用］をクリックします。
B21: 8 | C21: 列の型を設定 | D21: 各列の見出しの左にあるアイコン（ABC や 123）をクリックして、下の表のとおりに型を選びます。 | E21: 下の表を参照 | F21: 特に responseCode は必ず「テキスト」にします。
B22: 9 | C22: 日時の列を追加 | D22: ［列の追加］→［カスタム列］をクリックし、新しい列名と式を入力して［OK］。追加された列の型を［日付/時刻］にします。 | E22: 列名：開始日時JST 式：= #datetime(1970,1,1,9,0,0) + #duration(0,0,0,[timeStamp]/1000) | F22: 1970/1/1 からのミリ秒（UTC 基準）を、日本時間の日時に変換します。
B23: 10 | C23: シートに読み込む | D23: ［ホーム］→［閉じて読み込む］をクリックします。 | F23: 新しいシートに表（テーブル）として読み込まれます。
B24: 11 | C24: テーブル名を変える | D24: 表の中をクリック →［テーブル デザイン］タブ → 左端の［テーブル名］を書き換えます。 | E24: tblJTL | F24: 数式で tblJTL[elapsed] のように列を指定できるようになります（15 で使用）。
B25: 12 | C25: 日時の表示形式 | D25: 開始日時JST の列を選び、Ctrl＋1 →［表示形式］→［ユーザー定義］→ 種類に下の書式を入力 →［OK］。 | E25: yyyy/mm/dd hh:mm:ss.000 | F25: ミリ秒まで表示されます。
B26: 13 | C26: 件数の確認 | D26: 表のデータの件数（見出しを除く行数）が、試験の総リクエスト数と一致するか確認します。 | E26: 12 の run_test.sh が最後に表示する [INFO] samples の件数、または HTML レポートの Statistics の Total の #Samples | F26: 表の行を選ぶと、画面下のステータスバーに「データの個数」が表示されます。結果ファイルの行数とは一致しないことがあります（failureMessage の改行のため）。
B28: ［ 画像貼付エリア ］ 図14-1 ［テキストまたは CSV から］のプレビュー画面 撮影対象：元のファイル＝65001 : Unicode (UTF-8)、区切り記号＝コンマを選んだ状態 （この枠の左上のセルを選択して Ctrl+V で貼り付け、枠内に収まるようにサイズを調整してください）
B48: 図14-1 ［テキストまたは CSV から］のプレビュー画面
B50: ［ 画像貼付エリア ］ 図14-2 Power Query エディターで型とカスタム列を設定した画面 撮影対象：［ソース］の式が QuoteStyle.Csv、responseCode がテキスト型、開始日時JST の列を追加した状態 （この枠の左上のセルを選択して Ctrl+V で貼り付け、枠内に収まるようにサイズを調整してください）
B72: 図14-2 Power Query エディターで型とカスタム列を設定した画面
B75: 列のデータ型（手順8）
B77: 列 | D77: 型 | E77: 理由
B78: timeStamp | D78: 整数 | E78: 1970年1月1日からのミリ秒（13 桁の数値）
B79: elapsed、bytes、sentBytes、grpThreads、allThreads、Latency、IdleTime、Connect | D79: 整数 | E79: 時間（ミリ秒）・バイト数・スレッド数
B80: label、responseMessage、threadName、dataType、failureMessage、URL | D80: テキスト | E80: 文字列
B81: responseCode | D81: テキスト | E81: 通信エラーのときは「Non HTTP response code: java.net…」という文字列が入るため。整数にするとその行がエラーになり、エラーの件数を数え漏らします。
B82: success | D82: True/False | E82: 成功＝TRUE、失敗＝FALSE
B84: 参考 | C84: 数式で日時に変換する方法もあります（Power Query を使わない場合）。開始日時JST の列に =[@timeStamp]/86400000+DATE(1970,1,1)+TIME(9,0,0) と入力すると、日本時間の日時になります（86400000 は1日のミリ秒数、TIME(9,0,0) は＋9時間）。
B87: 3. 【別の方法】M コードを貼り付けて一度に取り込む
B89: 手順2～9 の画面操作は、Power Query の命令文（M コード）としても書けます。下のコードを貼り付けると、文字コード・区切り記号・引用符の中の改行・列の型・日本時間の列が一度に設定されます。画面操作に慣れたら、こちらの方が速く、設定漏れもありません。
B90: No. | C90: 手順 | D90: 操作内容（詳しい手順） | E90: 入力値・設定値 | F90: 確認ポイント・補足
B91: 1 | C91: 空のクエリを作る | D91: 分析用のブックで［データ］→［データの取得］→［その他のデータ ソースから］→［空のクエリ］をクリックします。 | F91: Power Query エディターが開きます。
B92: 2 | C92: 詳細エディターを開く | D92: ［ホーム］→［詳細エディター］をクリックします。 | F92: 最初から入っている「let … in …」の文字は、次の手順ですべて置き換えます。
B93: 3 | C93: コードを貼り付ける | D93: エディター内の文字をすべて選択（Ctrl＋A）して消し、下のコードを貼り付けます。FilePath の右側の "…" を、実際の result.jtl の場所に書き換えて［完了］をクリックします。 | E93: FilePath = "C:\work\jmeter\results\<フォルダ>\result.jtl", | F93: エクスプローラーでファイルを右クリック →［パスのコピー］でコピーした値は、前後に「"」が付いています。"…" の部分全体と置き換えます。
B94: 4 | C94: クエリの名前を変える | D94: 右側の［クエリの設定］→［プロパティ］の［名前］を書き換えます。 | E94: tblJTL | F94: 読み込んだ表（テーブル）にも通常は同じ名前が付きます。読み込み後のテーブル名が tblJTL になっていない場合は、手順11 で変更します。
...

Sheet 15_Excel分析
B1: 15 Excel での結果分析と報告書の作成
B2: 取り込んだ結果（テーブル tblJTL）から、API 別の統計表・時系列の集計・グラフを作り、目標値と比べて判定し、報告書にまとめる手順です。完成例は 16～18 のシートにあります。 | F2: ▲ 目次へ戻る
B4: 1. 分析ブックの構成（おすすめ）
B6: シート | D6: 内容 | F6: このブックの完成例
B7: JTL | D7: 取り込んだ生データ（テーブル tblJTL）＋ 分析用の補助列 | F7: 16_JTLサンプル
B8: 集計 | D8: 目標値と評価区間、試験全体の情報、API 別の統計（全区間・評価区間）と判定、エラーの内訳 | F8: 17_分析サンプル の1～5章
B9: 時系列・グラフ | D9: 1分ごとの件数・応答時間・エラー数と、そのグラフ | F9: 17_分析サンプル の6～7章
B10: 報告書 | D10: 提出用の様式 | F10: 18_報告書様式
B12: ポイント | C12: 16～18 のシートには、ダミーデータと数式が入った完成例があります。実際の分析では、16 の表を実データに置き換える（14 の手順で取り込んだ表に、下の補助列を追加する）と、17・18 の数値とグラフが自動で再計算されます。
B15: 2. STEP1：補助列を追加する
B17: tblJTL の右端の空いている列に見出しを入力すると、テーブルが自動で広がります。続けて1行目に数式を入力すると、全行に同じ数式が自動で入ります（[@列名] は「同じ行のその列」という意味です）。
B18: 列名（見出し） | D18: 数式（1行目に入力） | E18: 意味
B19: 開始日時JST | D19: =[@timeStamp]/86400000+DATE(1970,1,1)+TIME(9,0,0) | E19: 日本時間の開始日時（14 の手順9 や M コードで作った場合は不要）
B20: 終了ms | D20: =[@timeStamp]+[@elapsed] | E20: リクエストの終了時刻（ミリ秒）
B21: 経過秒 | D21: =([@timeStamp]-集計!$E$18)/1000 | E21: 試験開始からの経過秒。集計!$E$18 は試験開始（STEP2 の MIN）のセル
B22: 経過分 | D22: =INT([@経過秒]/60) | E22: 1分ごとに集計するための区分（0, 1, 2 …）
B23: エラー | D23: =IF(OR([@success]=FALSE,[@success]="false"),1,0) | E23: 失敗なら 1、成功なら 0（件数の合計に使う）
B24: 評価対象 | D24: =IF(AND([@経過秒]>=集計!$E$11,[@経過秒]<集計!$E$12),1,0) | E24: 評価区間（集計シートで入力する開始秒～終了秒）に開始したリクエストなら 1（STEP7 で使う）
B26: 参考 | C26: 完成例（16_JTLサンプル）では、「集計!$E$18」の部分が '17_分析サンプル'!$E$18 になっています。シート名に合わせて書き換えてください。
B29: 3. STEP2：試験全体の情報
B31: 項目 | D31: 数式 | E31: 表示形式
B32: 試験開始（エポックミリ秒） | D32: =MIN(tblJTL[timeStamp]) | E32: 0
B33: 試験開始（日本時間） | D33: =E18/86400000+DATE(1970,1,1)+TIME(9,0,0) | E33: yyyy/mm/dd hh:mm:ss
B34: 試験終了（日本時間） | D34: =MAX(tblJTL[終了ms])/86400000+DATE(1970,1,1)+TIME(9,0,0) | E34: yyyy/mm/dd hh:mm:ss
B35: 試験時間（秒） | D35: =(MAX(tblJTL[終了ms])-E18)/1000 | E35: #,##0.0
B36: 総リクエスト数 | D36: =COUNTA(tblJTL[label]) | E36: #,##0
B37: 総エラー数 | D37: =SUM(tblJTL[エラー]) | E37: #,##0
B38: 全体のエラー率 | D38: =IF(E22=0,0,E23/E22) | E38: 0.00%
B39: 最大スレッド数 | D39: =MAX(tblJTL[allThreads]) | E39: #,##0
B42: 4. STEP3：API（ラベル）別の統計表
B44: B 列にラベル名（例：A01_GET_items）を入れた行に、次の数式を入力します（例は 35 行目）。下の行へはコピーして使います。
B45: 項目 | D45: 数式（35 行目の例） | E45: 説明
B46: サンプル数 | D46: =COUNTIFS(tblJTL[label],$B35) | E46: そのラベルの件数
B47: 平均（ms） | D47: =AVERAGEIFS(tblJTL[elapsed],tblJTL[label],$B35) | E47: 平均応答時間
B48: 最小（ms） | D48: =AGGREGATE(15,6,tblJTL[elapsed]/(tblJTL[label]=$B35),1) | E48: 15＝SMALL（小さい方から1番目）
B49: 最大（ms） | D49: =AGGREGATE(14,6,tblJTL[elapsed]/(tblJTL[label]=$B35),1) | E49: 14＝LARGE（大きい方から1番目）
B50: 中央値（ms） | D50: =AGGREGATE(16,6,tblJTL[elapsed]/(tblJTL[label]=$B35),0.5) | E50: 16＝PERCENTILE.INC（50%）
B51: 90／95／99 パーセンタイル（ms） | D51: =AGGREGATE(16,6,tblJTL[elapsed]/(tblJTL[label]=$B35),0.9) | E51: 最後の 0.9 を 0.95、0.99 に変える
B52: エラー数 | D52: =SUMIFS(tblJTL[エラー],tblJTL[label],$B35) | E52: エラー列の合計
B53: エラー率 | D53: =IF(C35=0,0,K35/C35) | E53: エラー数÷サンプル数（表示形式 0.00%）
...

Sheet 16_JTLサンプル
B1: 16 JTL サンプル（分析練習用のダミーデータ：10 スレッド・600 秒）
B2: 本シートは分析手順の練習用に作成した架空の結果データです（実在のシステムの結果ではありません）。列 B～R は JMeter が出力する JTL の標準の17列、列 S～X（明るい灰色の見出し）は分析用に追加した補助列で、数式が入っています。実際の分析では、14 の手順で取り込んだ表に置き換えます。 | U2: ▲ 目次へ戻る
B5: timeStamp | C5: elapsed | D5: label | E5: responseCode | F5: responseMessage | G5: threadName | H5: dataType | I5: success | J5: failureMessage | K5: bytes | L5: sentBytes | M5: grpThreads | N5: allThreads | O5: URL | P5: Latency | Q5: IdleTime | R5: Connect | S5: 開始日時JST | T5: 終了ms | U5: 経過秒 | V5: 経過分 | W5: エラー | X5: 評価対象
B6: 1790816400180 | C6: 186 | D6: T01_Cognito_Token | E6: 200 | F6: OK | G6: setUp_Token 1-1 | H6: text | I6: TRUE | K6: 1561 | L6: 463 | M6: 1 | N6: 1 | O6: https://example-auth.auth.ap-northeast-1.amazoncognito.com/oauth2/token | P6: 183 | Q6: 0 | R6: 58 | S6: =tblJTL[[#This Row],[timeStamp]]/86400000+DATE(1970,1,1)+TIME(9,0,0) -> 46296.417 | T6: =tblJTL[[#This Row],[timeStamp]]+tblJTL[[#This Row],[elapsed]] -> 1790816400366 | U6: =(tblJTL[[#This Row],[timeStamp]]-'17_分析サンプル'!$E$18)/1000 -> 0 | V6: =INT(tblJTL[[#This Row],[経過秒]]/60) -> 0 | W6: =IF(OR(tblJTL[[#This Row],[success]]=FALSE,tblJTL[[#This Row],[success]]="false"),1,0) -> 0 | X6: =IF(AND(tblJTL[[#This Row],[経過秒]]>='17_分析サンプル'!$E$11,tblJTL[[#This Row],[経過秒]]<'17_分析サンプル'!$E$12),1,0) -> 0
B7: 1790816402070 | C7: 157 | D7: A01_GET_items | E7: 200 | F7: OK | G7: TG01_API 1-1 | H7: text | I7: TRUE | K7: 1900 | L7: 1342 | M7: 1 | N7: 1 | O7: https://abcde12345.execute-api.ap-northeast-1.amazonaws.com/stg/items?limit=10 | P7: 149 | Q7: 0 | R7: 65 | S7: =tblJTL[[#This Row],[timeStamp]]/86400000+DATE(1970,1,1)+TIME(9,0,0) -> 46296.417 | T7: =tblJTL[[#This Row],[timeStamp]]+tblJTL[[#This Row],[elapsed]] -> 1790816402227 | U7: =(tblJTL[[#This Row],[timeStamp]]-'17_分析サンプル'!$E$18)/1000 -> 1.89 | V7: =INT(tblJTL[[#This Row],[経過秒]]/60) -> 0 | W7: =IF(OR(tblJTL[[#This Row],[success]]=FALSE,tblJTL[[#This Row],[success]]="false"),1,0) -> 0 | X7: =IF(AND(tblJTL[[#This Row],[経過秒]]>='17_分析サンプル'!$E$11,tblJTL[[#This Row],[経過秒]]<'17_分析サンプル'!$E$12),1,0) -> 0
B8: 1790816403475 | C8: 312 | D8: A02_POST_orders | E8: 201 | F8: Created | G8: TG01_API 1-1 | H8: text | I8: TRUE | K8: 414 | L8: 1478 | M8: 1 | N8: 1 | O8: https://abcde12345.execute-api.ap-northeast-1.amazonaws.com/stg/orders | P8: 305 | Q8: 0 | R8: 0 | S8: =tblJTL[[#This Row],[timeStamp]]/86400000+DATE(1970,1,1)+TIME(9,0,0) -> 46296.417 | T8: =tblJTL[[#This Row],[timeStamp]]+tblJTL[[#This Row],[elapsed]] -> 1790816403787 | U8: =(tblJTL[[#This Row],[timeStamp]]-'17_分析サンプル'!$E$18)/1000 -> 3.295 | V8: =INT(tblJTL[[#This Row],[経過秒]]/60) -> 0 | W8: =IF(OR(tblJTL[[#This Row],[success]]=FALSE,tblJTL[[#This Row],[success]]="false"),1,0) -> 0 | X8: =IF(AND(tblJTL[[#This Row],[経過秒]]>='17_分析サンプル'!$E$11,tblJTL[[#This Row],[経過秒]]<'17_分析サンプル'!$E$12),1,0) -> 0
B9: 1790816404942 | C9: 169 | D9: A01_GET_items | E9: 200 | F9: OK | G9: TG01_API 1-1 | H9: text | I9: TRUE | K9: 1879 | L9: 1342 | M9: 1 | N9: 1 | O9: https://abcde12345.execute-api.ap-northeast-1.amazonaws.com/stg/items?limit=10 | P9: 165 | Q9: 0 | R9: 0 | S9: =tblJTL[[#This Row],[timeStamp]]/86400000+DATE(1970,1,1)+TIME(9,0,0) -> 46296.417 | T9: =tblJTL[[#This Row],[timeStamp]]+tblJTL[[#This Row],[elapsed]] -> 1790816405111 | U9: =(tblJTL[[#This Row],[timeStamp]]-'17_分析サンプル'!$E$18)/1000 -> 4.762 | V9: =INT(tblJTL[[#This Row],[経過秒]]/60) -> 0 | W9: =IF(OR(tblJTL[[#This Row],[success]]=FALSE,tblJTL[[#This Row],[success]]="false"),1,0) -> 0 | X9: =IF(AND(tblJTL[[#This Row],[経過秒]]>='17_分析サンプル'!$E$11,tblJTL[[#This Row],[経過秒]]<'17_分析サンプル'!$E$12),1,0) -> 0
B10: 1790816406494 | C10: 379 | D10: A02_POST_orders | E10: 201 | F10: Created | G10: TG01_API 1-1 | H10: text | I10: TRUE | K10: 438 | L10: 1478 | M10: 1 | N10: 1 | O10: https://abcde12345.execute-api.ap-northeast-1.amazonaws.com/stg/orders | P10: 371 | Q10: 0 | R10: 0 | S10: =tblJTL[[#This Row],[timeStamp]]/86400000+DATE(1970,1,1)+TIME(9,0,0) -> 46296.417 | T10: =tblJTL[[#This Row],[timeStamp]]+tblJTL[[#This Row],[elapsed]] -> 1790816406873 | U10: =(tblJTL[[#This Row],[timeStamp]]-'17_分析サンプル'!$E$18)/1000 -> 6.314 | V10: =INT(tblJTL[[#This Row],[経過秒]]/60) -> 0 | W10: =IF(OR(tblJTL[[#This Row],[success]]=FALSE,tblJTL[[#This Row],[success]]="false"),1,0) -> 0 | X10: =IF(AND(tblJTL[[#This Row],[経過秒]]>='17_分析サンプル'!$E$11,tblJTL[[#This Row],[経過秒]]<'17_分析サンプル'!$E$12),1,0) -> 0
